Workbook
Name L_JKP: Rujukan!$A$5:$A$13
Name S_JKP: Rujukan!$B$5:$B$13
Name T_JKP: Rujukan!$A$5:$B$13
Name L_JSP: Rujukan!$E$5:$E$24
Name S_JSP: Rujukan!$F$5:$F$24
Name T_JSP: Rujukan!$E$5:$F$24
Name L_JUB: Rujukan!$I$5:$I$72
Name S_JUB: Rujukan!$J$5:$J$72
Name T_JUB: Rujukan!$I$5:$J$72
Name L_KOM: Rujukan!$M$5:$M$17
Name S_KOM: Rujukan!$N$5:$N$17
Name T_KOM: Rujukan!$M$5:$N$17
Name L_KHID: Rujukan!$Q$5:$Q$8
Name S_KHID: Rujukan!$R$5:$R$8
Name T_KHID: Rujukan!$Q$5:$R$8
Name L_PER: Rujukan!$U$5:$U$10
Name S_PER: Rujukan!$V$5:$V$10
Name T_PER: Rujukan!$U$5:$V$10
Name L_JENIS: Rujukan!$Y$5:$Y$7
Name S_JENIS: Rujukan!$Z$5:$Z$7
Name T_JENIS: Rujukan!$Y$5:$Z$7
Name L_KED: Rujukan!$AC$5:$AC$9
Name S_KED: Rujukan!$AD$5:$AD$9
Name T_KED: Rujukan!$AC$5:$AD$9
Name T_LIBAT: Rujukan!$AH$5:$AJ$10
Name T_CAPAI: Rujukan!$AM$5:$AQ$10
Name L_PERK: Rujukan!$AS$5:$AS$11
Name S_PERK: Rujukan!$AT$5:$AT$11
Name T_PERK: Rujukan!$AS$5:$AT$11
Name L_ANUG: Rujukan!$AW$5:$AW$20
Name S_ANUG: Rujukan!$AX$5:$AX$20
Name T_ANUG: Rujukan!$AW$5:$AX$20
Name L_NILAM: Rujukan!$BA$5:$BA$9
Name S_NILAM: Rujukan!$BB$5:$BB$9
Name T_NILAM: Rujukan!$BA$5:$BB$9
Name L_TIMSS: Rujukan!$BE$5:$BE$7
Name S_TIMSS: Rujukan!$BF$5:$BF$7
Name T_TIMSS: Rujukan!$BE$5:$BF$7
Name L_STATUS: Rujukan!$BI$5:$BI$6
Name S_STATUS: Rujukan!$BJ$5:$BJ$6
Name T_STATUS: Rujukan!$BI$5:$BJ$6

Sheet Panduan
A1: TEMPLAT KIRAAN PAJSK 2026 · SEKOLAH MENENGAH
A2: Berdasarkan Garis Panduan PAJSK Sekolah Menengah (KPM) dan diselaraskan dengan paparan MOEIS SPPB.
B5: CARA GUNA
B6: 1. Murid | C6: Isi Nama, No. MyKad, Tingkatan dan Kelas. MyKad mesti tepat (robot padankan murid melalui MyKad). Status TL = tidak ditaksir (robot akan matikan suis DITAKSIR).
B7: 2. KP, UB, SP | C7: Guru penasihat tapis (filter) lajur "Unit / Aktiviti Utama", kemudian isi petak kuning.
B8: 3. Ekstra | C8: Isi ikut 5 bahagian tab Ekstra Kurikulum MOEIS.
B9: 4. Rumusan | C9: GPA dan Gred dikira automatik. Semak sebelum dimasukkan ke MOEIS.
B10: 5. Robot PAJSK | C10: Robot membaca fail ini dan mengisi halaman pensel MOEIS. Guru semak dan tekan Simpan sendiri. Nama unit sekolah dipadankan dengan senarai aktiviti MOEIS sekali sahaja dalam robot. Jangan ubah susunan lajur atau teks pilihan.
B12: PETUNJUK WARNA
B13: Petak kuning | C13: Diisi oleh guru (pilih daripada senarai dropdown).
B14: Petak putih | C14: Formula automatik. Jangan diubah.
B15: Petak merah | C15: Amaran: komitmen berulang, atau peringkat/jenis tidak lengkap.
B17: PECAHAN MARKAH SETIAP BIDANG (KP / UB / SP) = 110
B18: Jawatan (10) | C18: Senarai jawatan sama seperti dropdown MOEIS. Aktiviti utama sahaja.
B19: Kehadiran (40) | C19: 12 perjumpaan = 40. Setiap kali hadir = 3.33.
B20: Komitmen (10) | C20: Maksimum 4 pilihan. Aktiviti utama sahaja.
B21: Khidmat Sumbangan (10) | C21: Maksimum 1 pilihan, peringkat sekolah. Aktiviti utama sahaja.
B22: Pelibatan (20) | C22: Peringkat x Pelibatan 1/2/3. Peringkat sekolah = 0. Ambil tertinggi (utama/tambahan).
B23: Pencapaian (20) | C23: Peringkat x Kedudukan (Johan-Kelima). Ambil tertinggi (utama/tambahan).
B24: Markah 100 | C24: Jumlah / 110 x 100. Sama seperti "Markah Peratus" dalam MOEIS (contoh: 4 -> 3.64).
B26: GPA DAN GRED
B27: GPA | C27: Purata 2 markah terbaik daripada KP, UB, SP + Ekstra Kurikulum (maks. 10).
B28: Contoh (Jadual 20) | C28: KP 86, UB 70, SP 59, Ekstra 5 -> (86 + 70) / 2 = 78 -> 78 + 5 = 83 (Gred A)
B29: Gred | C29: A 80-100 Cemerlang · B 60-79.9 Kepujian · C 40-59.9 Baik · D 20-39.9 Kurang Memuaskan · E 0-19.9 Tidak Memuaskan · TL Tidak Laksana
B31: CONTOH SATU MURID (format pengisian)
B32: Unit | C32: KELAB SEJARAH
B33: Jawatan | C33: SETIAUSAHA -> 7
B34: Bil. Hadir | C34: 10 -> 33.30
B35: Komitmen | C35: MENEPATI WAKTU, MENUNJUKKAN MINAT, MENGIKUT ARAHAN, MEMBERI KERJASAMA -> 8
B36: Khidmat Sumbangan | C36: 4 - SOKONGAN -> 5
B37: Pelibatan | C37: ZON/DAERAH + PELIBATAN 1 -> 11
B38: Pencapaian | C38: ZON/DAERAH + KETIGA -> 9
B39: Jumlah | C39: 73.30 / 110 -> Markah 66.64 / 100
B41: ANDAIAN & CATATAN
B42: • Sumber setiap skor ditunjukkan dalam sheet Rujukan: MOEIS (disahkan), Garis panduan, atau Anggaran (merah).
B43: • Skor jawatan dalam MOEIS berbeza dengan Jadual 3 garis panduan (contoh: SETIAUSAHA = 7 dalam MOEIS, 8 dalam PDF). Templat mengikut MOEIS.
B44: • Pencapaian peringkat BAHAGIAN (SABAH/SARAWAK) tiada dalam garis panduan: skor anggaran.
B45: • Kehadiran 7 kali: jadual garis panduan menulis 23.21, tetapi 7 x 3.33 = 23.31. Templat guna 23.31.
B46: • Khidmat Masyarakat, NILAM dan Skor Ekstra: cara MOEIS mengira belum disahkan (anggaran).
B47: • GPA dihadkan maksimum 100.
...

Sheet Murid
A1: SENARAI MURID
A2: Isi petak kuning. Sheet lain mengambil nama daripada sini secara automatik. No. MyKad mesti tepat: robot memadankan murid MOEIS melalui MyKad.
A4: Bil | B4: Nama Murid | C4: No. MyKad | D4: Tingkatan | E4: Kelas | F4: Status | G4: Catatan
A5: =IF(B5="","",1)
A6: =IF(B6="","",2)
A7: =IF(B7="","",3)
A8: =IF(B8="","",4)
A9: =IF(B9="","",5)
A10: =IF(B10="","",6)
A11: =IF(B11="","",7)
A12: =IF(B12="","",8)
A13: =IF(B13="","",9)
A14: =IF(B14="","",10)
A15: =IF(B15="","",11)
A16: =IF(B16="","",12)
A17: =IF(B17="","",13)
A18: =IF(B18="","",14)
A19: =IF(B19="","",15)
A20: =IF(B20="","",16)
A21: =IF(B21="","",17)
A22: =IF(B22="","",18)
A23: =IF(B23="","",19)
A24: =IF(B24="","",20)
A25: =IF(B25="","",21)
A26: =IF(B26="","",22)
A27: =IF(B27="","",23)
A28: =IF(B28="","",24)
A29: =IF(B29="","",25)
A30: =IF(B30="","",26)
A31: =IF(B31="","",27)
A32: =IF(B32="","",28)
A33: =IF(B33="","",29)
A34: =IF(B34="","",30)
A35: =IF(B35="","",31)
A36: =IF(B36="","",32)
A37: =IF(B37="","",33)
A38: =IF(B38="","",34)
A39: =IF(B39="","",35)
A40: =IF(B40="","",36)
A41: =IF(B41="","",37)
...

Sheet KP
A1: KELAB & PERSATUAN (KP)
A2: Isi petak kuning. Pelibatan & Pencapaian: ambil yang TERTINGGI (aktiviti utama atau tambahan). Jawatan, Komitmen & Khidmat: aktiviti utama sahaja.
F3: Jawatan | H3: Kehadiran | J3: Komitmen (maks. 4 pilihan) | O3: Khidmat Sumbangan | Q3: Pelibatan | T3: Pencapaian | W3: Markah
A4: Bil | B4: Nama Murid | C4: No. MyKad | D4: Kelas | E4: Unit / Aktiviti Utama | F4: Jawatan | G4: Skor Jawatan | H4: Bil. Hadir (0-12) | I4: Skor Hadir (40) | J4: Komitmen 1 | K4: Komitmen 2 | L4: Komitmen 3 | M4: Komitmen 4 | N4: Skor Komitmen (10) | O4: Khidmat Sumbangan | P4: Skor Khidmat (10) | Q4: Pelibatan: Peringkat | R4: Pelibatan: Jenis | S4: Skor Pelibatan (20) | T4: Pencapaian: Peringkat | U4: Pencapaian: Kedudukan | V4: Skor Pencapaian (20) | W4: Jumlah (110) | X4: Markah (100)
A5: =Murid!A5 | B5: =IF(Murid!B5="","",Murid!B5) | C5: =IF(Murid!C5="","",Murid!C5) | D5: =IF(Murid!E5="","",Murid!E5) | G5: =IF(F5="","",IFERROR(VLOOKUP(F5,T_JKP,2,FALSE),0)) | I5: =IF(H5="","",IF(H5>=12,40,ROUND(H5*3.33,2))) | N5: =IF(COUNTA(J5:M5)=0,"",MIN(10,SUMPRODUCT((COUNTIF(J5:M5,L_KOM)>0)*S_KOM))) | P5: =IF(O5="","",IFERROR(VLOOKUP(O5,T_KHID,2,FALSE),0)) | S5: =IF(AND(Q5="",R5=""),"",IFERROR(INDEX(T_LIBAT,MATCH(Q5,L_PER,0),MATCH(R5,L_JENIS,0)),0)) | V5: =IF(AND(T5="",U5=""),"",IFERROR(INDEX(T_CAPAI,MATCH(T5,L_PER,0),MATCH(U5,L_KED,0)),0)) | W5: =IF(OR(B5="",E5="",COUNTA(F5,H5,J5:M5,O5,Q5:R5,T5:U5)=0),"",SUM(G5,I5,N5,P5,S5,V5)) | X5: =IF(W5="","",IF(Murid!F5="TL","TL",ROUND(W5/110*100,2)))
A6: =Murid!A6 | B6: =IF(Murid!B6="","",Murid!B6) | C6: =IF(Murid!C6="","",Murid!C6) | D6: =IF(Murid!E6="","",Murid!E6) | G6: =IF(F6="","",IFERROR(VLOOKUP(F6,T_JKP,2,FALSE),0)) | I6: =IF(H6="","",IF(H6>=12,40,ROUND(H6*3.33,2))) | N6: =IF(COUNTA(J6:M6)=0,"",MIN(10,SUMPRODUCT((COUNTIF(J6:M6,L_KOM)>0)*S_KOM))) | P6: =IF(O6="","",IFERROR(VLOOKUP(O6,T_KHID,2,FALSE),0)) | S6: =IF(AND(Q6="",R6=""),"",IFERROR(INDEX(T_LIBAT,MATCH(Q6,L_PER,0),MATCH(R6,L_JENIS,0)),0)) | V6: =IF(AND(T6="",U6=""),"",IFERROR(INDEX(T_CAPAI,MATCH(T6,L_PER,0),MATCH(U6,L_KED,0)),0)) | W6: =IF(OR(B6="",E6="",COUNTA(F6,H6,J6:M6,O6,Q6:R6,T6:U6)=0),"",SUM(G6,I6,N6,P6,S6,V6)) | X6: =IF(W6="","",IF(Murid!F6="TL","TL",ROUND(W6/110*100,2)))
A7: =Murid!A7 | B7: =IF(Murid!B7="","",Murid!B7) | C7: =IF(Murid!C7="","",Murid!C7) | D7: =IF(Murid!E7="","",Murid!E7) | G7: =IF(F7="","",IFERROR(VLOOKUP(F7,T_JKP,2,FALSE),0)) | I7: =IF(H7="","",IF(H7>=12,40,ROUND(H7*3.33,2))) | N7: =IF(COUNTA(J7:M7)=0,"",MIN(10,SUMPRODUCT((COUNTIF(J7:M7,L_KOM)>0)*S_KOM))) | P7: =IF(O7="","",IFERROR(VLOOKUP(O7,T_KHID,2,FALSE),0)) | S7: =IF(AND(Q7="",R7=""),"",IFERROR(INDEX(T_LIBAT,MATCH(Q7,L_PER,0),MATCH(R7,L_JENIS,0)),0)) | V7: =IF(AND(T7="",U7=""),"",IFERROR(INDEX(T_CAPAI,MATCH(T7,L_PER,0),MATCH(U7,L_KED,0)),0)) | W7: =IF(OR(B7="",E7="",COUNTA(F7,H7,J7:M7,O7,Q7:R7,T7:U7)=0),"",SUM(G7,I7,N7,P7,S7,V7)) | X7: =IF(W7="","",IF(Murid!F7="TL","TL",ROUND(W7/110*100,2)))
A8: =Murid!A8 | B8: =IF(Murid!B8="","",Murid!B8) | C8: =IF(Murid!C8="","",Murid!C8) | D8: =IF(Murid!E8="","",Murid!E8) | G8: =IF(F8="","",IFERROR(VLOOKUP(F8,T_JKP,2,FALSE),0)) | I8: =IF(H8="","",IF(H8>=12,40,ROUND(H8*3.33,2))) | N8: =IF(COUNTA(J8:M8)=0,"",MIN(10,SUMPRODUCT((COUNTIF(J8:M8,L_KOM)>0)*S_KOM))) | P8: =IF(O8="","",IFERROR(VLOOKUP(O8,T_KHID,2,FALSE),0)) | S8: =IF(AND(Q8="",R8=""),"",IFERROR(INDEX(T_LIBAT,MATCH(Q8,L_PER,0),MATCH(R8,L_JENIS,0)),0)) | V8: =IF(AND(T8="",U8=""),"",IFERROR(INDEX(T_CAPAI,MATCH(T8,L_PER,0),MATCH(U8,L_KED,0)),0)) | W8: =IF(OR(B8="",E8="",COUNTA(F8,H8,J8:M8,O8,Q8:R8,T8:U8)=0),"",SUM(G8,I8,N8,P8,S8,V8)) | X8: =IF(W8="","",IF(Murid!F8="TL","TL",ROUND(W8/110*100,2)))
A9: =Murid!A9 | B9: =IF(Murid!B9="","",Murid!B9) | C9: =IF(Murid!C9="","",Murid!C9) | D9: =IF(Murid!E9="","",Murid!E9) | G9: =IF(F9="","",IFERROR(VLOOKUP(F9,T_JKP,2,FALSE),0)) | I9: =IF(H9="","",IF(H9>=12,40,ROUND(H9*3.33,2))) | N9: =IF(COUNTA(J9:M9)=0,"",MIN(10,SUMPRODUCT((COUNTIF(J9:M9,L_KOM)>0)*S_KOM))) | P9: =IF(O9="","",IFERROR(VLOOKUP(O9,T_KHID,2,FALSE),0)) | S9: =IF(AND(Q9="",R9=""),"",IFERROR(INDEX(T_LIBAT,MATCH(Q9,L_PER,0),MATCH(R9,L_JENIS,0)),0)) | V9: =IF(AND(T9="",U9=""),"",IFERROR(INDEX(T_CAPAI,MATCH(T9,L_PER,0),MATCH(U9,L_KED,0)),0)) | W9: =IF(OR(B9="",E9="",COUNTA(F9,H9,J9:M9,O9,Q9:R9,T9:U9)=0),"",SUM(G9,I9,N9,P9,S9,V9)) | X9: =IF(W9="","",IF(Murid!F9="TL","TL",ROUND(W9/110*100,2)))
A10: =Murid!A10 | B10: =IF(Murid!B10="","",Murid!B10) | C10: =IF(Murid!C10="","",Murid!C10) | D10: =IF(Murid!E10="","",Murid!E10) | G10: =IF(F10="","",IFERROR(VLOOKUP(F10,T_JKP,2,FALSE),0)) | I10: =IF(H10="","",IF(H10>=12,40,ROUND(H10*3.33,2))) | N10: =IF(COUNTA(J10:M10)=0,"",MIN(10,SUMPRODUCT((COUNTIF(J10:M10,L_KOM)>0)*S_KOM))) | P10: =IF(O10="","",IFERROR(VLOOKUP(O10,T_KHID,2,FALSE),0)) | S10: =IF(AND(Q10="",R10=""),"",IFERROR(INDEX(T_LIBAT,MATCH(Q10,L_PER,0),MATCH(R10,L_JENIS,0)),0)) | V10: =IF(AND(T10="",U10=""),"",IFERROR(INDEX(T_CAPAI,MATCH(T10,L_PER,0),MATCH(U10,L_KED,0)),0)) | W10: =IF(OR(B10="",E10="",COUNTA(F10,H10,J10:M10,O10,Q10:R10,T10:U10)=0),"",SUM(G10,I10,N10,P10,S10,V10)) | X10: =IF(W10="","",IF(Murid!F10="TL","TL",ROUND(W10/110*100,2)))
A11: =Murid!A11 | B11: =IF(Murid!B11="","",Murid!B11) | C11: =IF(Murid!C11="","",Murid!C11) | D11: =IF(Murid!E11="","",Murid!E11) | G11: =IF(F11="","",IFERROR(VLOOKUP(F11,T_JKP,2,FALSE),0)) | I11: =IF(H11="","",IF(H11>=12,40,ROUND(H11*3.33,2))) | N11: =IF(COUNTA(J11:M11)=0,"",MIN(10,SUMPRODUCT((COUNTIF(J11:M11,L_KOM)>0)*S_KOM))) | P11: =IF(O11="","",IFERROR(VLOOKUP(O11,T_KHID,2,FALSE),0)) | S11: =IF(AND(Q11="",R11=""),"",IFERROR(INDEX(T_LIBAT,MATCH(Q11,L_PER,0),MATCH(R11,L_JENIS,0)),0)) | V11: =IF(AND(T11="",U11=""),"",IFERROR(INDEX(T_CAPAI,MATCH(T11,L_PER,0),MATCH(U11,L_KED,0)),0)) | W11: =IF(OR(B11="",E11="",COUNTA(F11,H11,J11:M11,O11,Q11:R11,T11:U11)=0),"",SUM(G11,I11,N11,P11,S11,V11)) | X11: =IF(W11="","",IF(Murid!F11="TL","TL",ROUND(W11/110*100,2)))
A12: =Murid!A12 | B12: =IF(Murid!B12="","",Murid!B12) | C12: =IF(Murid!C12="","",Murid!C12) | D12: =IF(Murid!E12="","",Murid!E12) | G12: =IF(F12="","",IFERROR(VLOOKUP(F12,T_JKP,2,FALSE),0)) | I12: =IF(H12="","",IF(H12>=12,40,ROUND(H12*3.33,2))) | N12: =IF(COUNTA(J12:M12)=0,"",MIN(10,SUMPRODUCT((COUNTIF(J12:M12,L_KOM)>0)*S_KOM))) | P12: =IF(O12="","",IFERROR(VLOOKUP(O12,T_KHID,2,FALSE),0)) | S12: =IF(AND(Q12="",R12=""),"",IFERROR(INDEX(T_LIBAT,MATCH(Q12,L_PER,0),MATCH(R12,L_JENIS,0)),0)) | V12: =IF(AND(T12="",U12=""),"",IFERROR(INDEX(T_CAPAI,MATCH(T12,L_PER,0),MATCH(U12,L_KED,0)),0)) | W12: =IF(OR(B12="",E12="",COUNTA(F12,H12,J12:M12,O12,Q12:R12,T12:U12)=0),"",SUM(G12,I12,N12,P12,S12,V12)) | X12: =IF(W12="","",IF(Murid!F12="TL","TL",ROUND(W12/110*100,2)))
A13: =Murid!A13 | B13: =IF(Murid!B13="","",Murid!B13) | C13: =IF(Murid!C13="","",Murid!C13) | D13: =IF(Murid!E13="","",Murid!E13) | G13: =IF(F13="","",IFERROR(VLOOKUP(F13,T_JKP,2,FALSE),0)) | I13: =IF(H13="","",IF(H13>=12,40,ROUND(H13*3.33,2))) | N13: =IF(COUNTA(J13:M13)=0,"",MIN(10,SUMPRODUCT((COUNTIF(J13:M13,L_KOM)>0)*S_KOM))) | P13: =IF(O13="","",IFERROR(VLOOKUP(O13,T_KHID,2,FALSE),0)) | S13: =IF(AND(Q13="",R13=""),"",IFERROR(INDEX(T_LIBAT,MATCH(Q13,L_PER,0),MATCH(R13,L_JENIS,0)),0)) | V13: =IF(AND(T13="",U13=""),"",IFERROR(INDEX(T_CAPAI,MATCH(T13,L_PER,0),MATCH(U13,L_KED,0)),0)) | W13: =IF(OR(B13="",E13="",COUNTA(F13,H13,J13:M13,O13,Q13:R13,T13:U13)=0),"",SUM(G13,I13,N13,P13,S13,V13)) | X13: =IF(W13="","",IF(Murid!F13="TL","TL",ROUND(W13/110*100,2)))
A14: =Murid!A14 | B14: =IF(Murid!B14="","",Murid!B14) | C14: =IF(Murid!C14="","",Murid!C14) | D14: =IF(Murid!E14="","",Murid!E14) | G14: =IF(F14="","",IFERROR(VLOOKUP(F14,T_JKP,2,FALSE),0)) | I14: =IF(H14="","",IF(H14>=12,40,ROUND(H14*3.33,2))) | N14: =IF(COUNTA(J14:M14)=0,"",MIN(10,SUMPRODUCT((COUNTIF(J14:M14,L_KOM)>0)*S_KOM))) | P14: =IF(O14="","",IFERROR(VLOOKUP(O14,T_KHID,2,FALSE),0)) | S14: =IF(AND(Q14="",R14=""),"",IFERROR(INDEX(T_LIBAT,MATCH(Q14,L_PER,0),MATCH(R14,L_JENIS,0)),0)) | V14: =IF(AND(T14="",U14=""),"",IFERROR(INDEX(T_CAPAI,MATCH(T14,L_PER,0),MATCH(U14,L_KED,0)),0)) | W14: =IF(OR(B14="",E14="",COUNTA(F14,H14,J14:M14,O14,Q14:R14,T14:U14)=0),"",SUM(G14,I14,N14,P14,S14,V14)) | X14: =IF(W14="","",IF(Murid!F14="TL","TL",ROUND(W14/110*100,2)))
A15: =Murid!A15 | B15: =IF(Murid!B15="","",Murid!B15) | C15: =IF(Murid!C15="","",Murid!C15) | D15: =IF(Murid!E15="","",Murid!E15) | G15: =IF(F15="","",IFERROR(VLOOKUP(F15,T_JKP,2,FALSE),0)) | I15: =IF(H15="","",IF(H15>=12,40,ROUND(H15*3.33,2))) | N15: =IF(COUNTA(J15:M15)=0,"",MIN(10,SUMPRODUCT((COUNTIF(J15:M15,L_KOM)>0)*S_KOM))) | P15: =IF(O15="","",IFERROR(VLOOKUP(O15,T_KHID,2,FALSE),0)) | S15: =IF(AND(Q15="",R15=""),"",IFERROR(INDEX(T_LIBAT,MATCH(Q15,L_PER,0),MATCH(R15,L_JENIS,0)),0)) | V15: =IF(AND(T15="",U15=""),"",IFERROR(INDEX(T_CAPAI,MATCH(T15,L_PER,0),MATCH(U15,L_KED,0)),0)) | W15: =IF(OR(B15="",E15="",COUNTA(F15,H15,J15:M15,O15,Q15:R15,T15:U15)=0),"",SUM(G15,I15,N15,P15,S15,V15)) | X15: =IF(W15="","",IF(Murid!F15="TL","TL",ROUND(W15/110*100,2)))
A16: =Murid!A16 | B16: =IF(Murid!B16="","",Murid!B16) | C16: =IF(Murid!C16="","",Murid!C16) | D16: =IF(Murid!E16="","",Murid!E16) | G16: =IF(F16="","",IFERROR(VLOOKUP(F16,T_JKP,2,FALSE),0)) | I16: =IF(H16="","",IF(H16>=12,40,ROUND(H16*3.33,2))) | N16: =IF(COUNTA(J16:M16)=0,"",MIN(10,SUMPRODUCT((COUNTIF(J16:M16,L_KOM)>0)*S_KOM))) | P16: =IF(O16="","",IFERROR(VLOOKUP(O16,T_KHID,2,FALSE),0)) | S16: =IF(AND(Q16="",R16=""),"",IFERROR(INDEX(T_LIBAT,MATCH(Q16,L_PER,0),MATCH(R16,L_JENIS,0)),0)) | V16: =IF(AND(T16="",U16=""),"",IFERROR(INDEX(T_CAPAI,MATCH(T16,L_PER,0),MATCH(U16,L_KED,0)),0)) | W16: =IF(OR(B16="",E16="",COUNTA(F16,H16,J16:M16,O16,Q16:R16,T16:U16)=0),"",SUM(G16,I16,N16,P16,S16,V16)) | X16: =IF(W16="","",IF(Murid!F16="TL","TL",ROUND(W16/110*100,2)))
... A1004: =Murid!A1004 | B1004: =IF(Murid!B1004="","",Murid!B1004) | C1004: =IF(Murid!C1004="","",Murid!C1004) | D1004: =IF(Murid!E1004="","",Murid!E1004) | G1004: =IF(F1004="","",IFERROR(VLOOKUP(F1004,T_JKP,2,FALSE),0)) | I1004: =IF(H1004="","",IF(H1004>=12,40,ROUND(H1004*3.33,2))) | N1004: =IF(COUNTA(J1004:M1004)=0,"",MIN(10,SUMPRODUCT((COUNTIF(J1004:M1004,L_KOM)>0)*S_KOM))) | P1004: =IF(O1004="","",IFERROR(VLOOKUP(O1004,T_KHID,2,FALSE),0)) | S1004: =IF(AND(Q1004="",R1004=""),"",IFERROR(INDEX(T_LIBAT,MATCH(Q1004,L_PER,0),MATCH(R1004,L_JENIS,0)),0)) | V1004: =IF(AND(T1004="",U1004=""),"",IFERROR(INDEX(T_CAPAI,MATCH(T1004,L_PER,0),MATCH(U1004,L_KED,0)),0)) | W1004: =IF(OR(B1004="",E1004="",COUNTA(F1004,H1004,J1004:M1004,O1004,Q1004:R1004,T1004:U1004)=0),"",SUM(G1004,I1004,N1004,P1004,S1004,V1004)) | X1004: =IF(W1004="","",IF(Murid!F1004="TL","TL",ROUND(W1004/110*100,2)))

Sheet UB
A1: BADAN BERUNIFORM (UB)
A2: Isi petak kuning. Pelibatan & Pencapaian: ambil yang TERTINGGI (aktiviti utama atau tambahan). Jawatan, Komitmen & Khidmat: aktiviti utama sahaja.
F3: Jawatan | H3: Kehadiran | J3: Komitmen (maks. 4 pilihan) | O3: Khidmat Sumbangan | Q3: Pelibatan | T3: Pencapaian | W3: Markah
A4: Bil | B4: Nama Murid | C4: No. MyKad | D4: Kelas | E4: Unit / Aktiviti Utama | F4: Jawatan | G4: Skor Jawatan | H4: Bil. Hadir (0-12) | I4: Skor Hadir (40) | J4: Komitmen 1 | K4: Komitmen 2 | L4: Komitmen 3 | M4: Komitmen 4 | N4: Skor Komitmen (10) | O4: Khidmat Sumbangan | P4: Skor Khidmat (10) | Q4: Pelibatan: Peringkat | R4: Pelibatan: Jenis | S4: Skor Pelibatan (20) | T4: Pencapaian: Peringkat | U4: Pencapaian: Kedudukan | V4: Skor Pencapaian (20) | W4: Jumlah (110) | X4: Markah (100)
A5: =Murid!A5 | B5: =IF(Murid!B5="","",Murid!B5) | C5: =IF(Murid!C5="","",Murid!C5) | D5: =IF(Murid!E5="","",Murid!E5) | G5: =IF(F5="","",IFERROR(VLOOKUP(F5,T_JUB,2,FALSE),0)) | I5: =IF(H5="","",IF(H5>=12,40,ROUND(H5*3.33,2))) | N5: =IF(COUNTA(J5:M5)=0,"",MIN(10,SUMPRODUCT((COUNTIF(J5:M5,L_KOM)>0)*S_KOM))) | P5: =IF(O5="","",IFERROR(VLOOKUP(O5,T_KHID,2,FALSE),0)) | S5: =IF(AND(Q5="",R5=""),"",IFERROR(INDEX(T_LIBAT,MATCH(Q5,L_PER,0),MATCH(R5,L_JENIS,0)),0)) | V5: =IF(AND(T5="",U5=""),"",IFERROR(INDEX(T_CAPAI,MATCH(T5,L_PER,0),MATCH(U5,L_KED,0)),0)) | W5: =IF(OR(B5="",E5="",COUNTA(F5,H5,J5:M5,O5,Q5:R5,T5:U5)=0),"",SUM(G5,I5,N5,P5,S5,V5)) | X5: =IF(W5="","",IF(Murid!F5="TL","TL",ROUND(W5/110*100,2)))
A6: =Murid!A6 | B6: =IF(Murid!B6="","",Murid!B6) | C6: =IF(Murid!C6="","",Murid!C6) | D6: =IF(Murid!E6="","",Murid!E6) | G6: =IF(F6="","",IFERROR(VLOOKUP(F6,T_JUB,2,FALSE),0)) | I6: =IF(H6="","",IF(H6>=12,40,ROUND(H6*3.33,2))) | N6: =IF(COUNTA(J6:M6)=0,"",MIN(10,SUMPRODUCT((COUNTIF(J6:M6,L_KOM)>0)*S_KOM))) | P6: =IF(O6="","",IFERROR(VLOOKUP(O6,T_KHID,2,FALSE),0)) | S6: =IF(AND(Q6="",R6=""),"",IFERROR(INDEX(T_LIBAT,MATCH(Q6,L_PER,0),MATCH(R6,L_JENIS,0)),0)) | V6: =IF(AND(T6="",U6=""),"",IFERROR(INDEX(T_CAPAI,MATCH(T6,L_PER,0),MATCH(U6,L_KED,0)),0)) | W6: =IF(OR(B6="",E6="",COUNTA(F6,H6,J6:M6,O6,Q6:R6,T6:U6)=0),"",SUM(G6,I6,N6,P6,S6,V6)) | X6: =IF(W6="","",IF(Murid!F6="TL","TL",ROUND(W6/110*100,2)))
A7: =Murid!A7 | B7: =IF(Murid!B7="","",Murid!B7) | C7: =IF(Murid!C7="","",Murid!C7) | D7: =IF(Murid!E7="","",Murid!E7) | G7: =IF(F7="","",IFERROR(VLOOKUP(F7,T_JUB,2,FALSE),0)) | I7: =IF(H7="","",IF(H7>=12,40,ROUND(H7*3.33,2))) | N7: =IF(COUNTA(J7:M7)=0,"",MIN(10,SUMPRODUCT((COUNTIF(J7:M7,L_KOM)>0)*S_KOM))) | P7: =IF(O7="","",IFERROR(VLOOKUP(O7,T_KHID,2,FALSE),0)) | S7: =IF(AND(Q7="",R7=""),"",IFERROR(INDEX(T_LIBAT,MATCH(Q7,L_PER,0),MATCH(R7,L_JENIS,0)),0)) | V7: =IF(AND(T7="",U7=""),"",IFERROR(INDEX(T_CAPAI,MATCH(T7,L_PER,0),MATCH(U7,L_KED,0)),0)) | W7: =IF(OR(B7="",E7="",COUNTA(F7,H7,J7:M7,O7,Q7:R7,T7:U7)=0),"",SUM(G7,I7,N7,P7,S7,V7)) | X7: =IF(W7="","",IF(Murid!F7="TL","TL",ROUND(W7/110*100,2)))
A8: =Murid!A8 | B8: =IF(Murid!B8="","",Murid!B8) | C8: =IF(Murid!C8="","",Murid!C8) | D8: =IF(Murid!E8="","",Murid!E8) | G8: =IF(F8="","",IFERROR(VLOOKUP(F8,T_JUB,2,FALSE),0)) | I8: =IF(H8="","",IF(H8>=12,40,ROUND(H8*3.33,2))) | N8: =IF(COUNTA(J8:M8)=0,"",MIN(10,SUMPRODUCT((COUNTIF(J8:M8,L_KOM)>0)*S_KOM))) | P8: =IF(O8="","",IFERROR(VLOOKUP(O8,T_KHID,2,FALSE),0)) | S8: =IF(AND(Q8="",R8=""),"",IFERROR(INDEX(T_LIBAT,MATCH(Q8,L_PER,0),MATCH(R8,L_JENIS,0)),0)) | V8: =IF(AND(T8="",U8=""),"",IFERROR(INDEX(T_CAPAI,MATCH(T8,L_PER,0),MATCH(U8,L_KED,0)),0)) | W8: =IF(OR(B8="",E8="",COUNTA(F8,H8,J8:M8,O8,Q8:R8,T8:U8)=0),"",SUM(G8,I8,N8,P8,S8,V8)) | X8: =IF(W8="","",IF(Murid!F8="TL","TL",ROUND(W8/110*100,2)))
A9: =Murid!A9 | B9: =IF(Murid!B9="","",Murid!B9) | C9: =IF(Murid!C9="","",Murid!C9) | D9: =IF(Murid!E9="","",Murid!E9) | G9: =IF(F9="","",IFERROR(VLOOKUP(F9,T_JUB,2,FALSE),0)) | I9: =IF(H9="","",IF(H9>=12,40,ROUND(H9*3.33,2))) | N9: =IF(COUNTA(J9:M9)=0,"",MIN(10,SUMPRODUCT((COUNTIF(J9:M9,L_KOM)>0)*S_KOM))) | P9: =IF(O9="","",IFERROR(VLOOKUP(O9,T_KHID,2,FALSE),0)) | S9: =IF(AND(Q9="",R9=""),"",IFERROR(INDEX(T_LIBAT,MATCH(Q9,L_PER,0),MATCH(R9,L_JENIS,0)),0)) | V9: =IF(AND(T9="",U9=""),"",IFERROR(INDEX(T_CAPAI,MATCH(T9,L_PER,0),MATCH(U9,L_KED,0)),0)) | W9: =IF(OR(B9="",E9="",COUNTA(F9,H9,J9:M9,O9,Q9:R9,T9:U9)=0),"",SUM(G9,I9,N9,P9,S9,V9)) | X9: =IF(W9="","",IF(Murid!F9="TL","TL",ROUND(W9/110*100,2)))
A10: =Murid!A10 | B10: =IF(Murid!B10="","",Murid!B10) | C10: =IF(Murid!C10="","",Murid!C10) | D10: =IF(Murid!E10="","",Murid!E10) | G10: =IF(F10="","",IFERROR(VLOOKUP(F10,T_JUB,2,FALSE),0)) | I10: =IF(H10="","",IF(H10>=12,40,ROUND(H10*3.33,2))) | N10: =IF(COUNTA(J10:M10)=0,"",MIN(10,SUMPRODUCT((COUNTIF(J10:M10,L_KOM)>0)*S_KOM))) | P10: =IF(O10="","",IFERROR(VLOOKUP(O10,T_KHID,2,FALSE),0)) | S10: =IF(AND(Q10="",R10=""),"",IFERROR(INDEX(T_LIBAT,MATCH(Q10,L_PER,0),MATCH(R10,L_JENIS,0)),0)) | V10: =IF(AND(T10="",U10=""),"",IFERROR(INDEX(T_CAPAI,MATCH(T10,L_PER,0),MATCH(U10,L_KED,0)),0)) | W10: =IF(OR(B10="",E10="",COUNTA(F10,H10,J10:M10,O10,Q10:R10,T10:U10)=0),"",SUM(G10,I10,N10,P10,S10,V10)) | X10: =IF(W10="","",IF(Murid!F10="TL","TL",ROUND(W10/110*100,2)))
A11: =Murid!A11 | B11: =IF(Murid!B11="","",Murid!B11) | C11: =IF(Murid!C11="","",Murid!C11) | D11: =IF(Murid!E11="","",Murid!E11) | G11: =IF(F11="","",IFERROR(VLOOKUP(F11,T_JUB,2,FALSE),0)) | I11: =IF(H11="","",IF(H11>=12,40,ROUND(H11*3.33,2))) | N11: =IF(COUNTA(J11:M11)=0,"",MIN(10,SUMPRODUCT((COUNTIF(J11:M11,L_KOM)>0)*S_KOM))) | P11: =IF(O11="","",IFERROR(VLOOKUP(O11,T_KHID,2,FALSE),0)) | S11: =IF(AND(Q11="",R11=""),"",IFERROR(INDEX(T_LIBAT,MATCH(Q11,L_PER,0),MATCH(R11,L_JENIS,0)),0)) | V11: =IF(AND(T11="",U11=""),"",IFERROR(INDEX(T_CAPAI,MATCH(T11,L_PER,0),MATCH(U11,L_KED,0)),0)) | W11: =IF(OR(B11="",E11="",COUNTA(F11,H11,J11:M11,O11,Q11:R11,T11:U11)=0),"",SUM(G11,I11,N11,P11,S11,V11)) | X11: =IF(W11="","",IF(Murid!F11="TL","TL",ROUND(W11/110*100,2)))
A12: =Murid!A12 | B12: =IF(Murid!B12="","",Murid!B12) | C12: =IF(Murid!C12="","",Murid!C12) | D12: =IF(Murid!E12="","",Murid!E12) | G12: =IF(F12="","",IFERROR(VLOOKUP(F12,T_JUB,2,FALSE),0)) | I12: =IF(H12="","",IF(H12>=12,40,ROUND(H12*3.33,2))) | N12: =IF(COUNTA(J12:M12)=0,"",MIN(10,SUMPRODUCT((COUNTIF(J12:M12,L_KOM)>0)*S_KOM))) | P12: =IF(O12="","",IFERROR(VLOOKUP(O12,T_KHID,2,FALSE),0)) | S12: =IF(AND(Q12="",R12=""),"",IFERROR(INDEX(T_LIBAT,MATCH(Q12,L_PER,0),MATCH(R12,L_JENIS,0)),0)) | V12: =IF(AND(T12="",U12=""),"",IFERROR(INDEX(T_CAPAI,MATCH(T12,L_PER,0),MATCH(U12,L_KED,0)),0)) | W12: =IF(OR(B12="",E12="",COUNTA(F12,H12,J12:M12,O12,Q12:R12,T12:U12)=0),"",SUM(G12,I12,N12,P12,S12,V12)) | X12: =IF(W12="","",IF(Murid!F12="TL","TL",ROUND(W12/110*100,2)))
A13: =Murid!A13 | B13: =IF(Murid!B13="","",Murid!B13) | C13: =IF(Murid!C13="","",Murid!C13) | D13: =IF(Murid!E13="","",Murid!E13) | G13: =IF(F13="","",IFERROR(VLOOKUP(F13,T_JUB,2,FALSE),0)) | I13: =IF(H13="","",IF(H13>=12,40,ROUND(H13*3.33,2))) | N13: =IF(COUNTA(J13:M13)=0,"",MIN(10,SUMPRODUCT((COUNTIF(J13:M13,L_KOM)>0)*S_KOM))) | P13: =IF(O13="","",IFERROR(VLOOKUP(O13,T_KHID,2,FALSE),0)) | S13: =IF(AND(Q13="",R13=""),"",IFERROR(INDEX(T_LIBAT,MATCH(Q13,L_PER,0),MATCH(R13,L_JENIS,0)),0)) | V13: =IF(AND(T13="",U13=""),"",IFERROR(INDEX(T_CAPAI,MATCH(T13,L_PER,0),MATCH(U13,L_KED,0)),0)) | W13: =IF(OR(B13="",E13="",COUNTA(F13,H13,J13:M13,O13,Q13:R13,T13:U13)=0),"",SUM(G13,I13,N13,P13,S13,V13)) | X13: =IF(W13="","",IF(Murid!F13="TL","TL",ROUND(W13/110*100,2)))
A14: =Murid!A14 | B14: =IF(Murid!B14="","",Murid!B14) | C14: =IF(Murid!C14="","",Murid!C14) | D14: =IF(Murid!E14="","",Murid!E14) | G14: =IF(F14="","",IFERROR(VLOOKUP(F14,T_JUB,2,FALSE),0)) | I14: =IF(H14="","",IF(H14>=12,40,ROUND(H14*3.33,2))) | N14: =IF(COUNTA(J14:M14)=0,"",MIN(10,SUMPRODUCT((COUNTIF(J14:M14,L_KOM)>0)*S_KOM))) | P14: =IF(O14="","",IFERROR(VLOOKUP(O14,T_KHID,2,FALSE),0)) | S14: =IF(AND(Q14="",R14=""),"",IFERROR(INDEX(T_LIBAT,MATCH(Q14,L_PER,0),MATCH(R14,L_JENIS,0)),0)) | V14: =IF(AND(T14="",U14=""),"",IFERROR(INDEX(T_CAPAI,MATCH(T14,L_PER,0),MATCH(U14,L_KED,0)),0)) | W14: =IF(OR(B14="",E14="",COUNTA(F14,H14,J14:M14,O14,Q14:R14,T14:U14)=0),"",SUM(G14,I14,N14,P14,S14,V14)) | X14: =IF(W14="","",IF(Murid!F14="TL","TL",ROUND(W14/110*100,2)))
A15: =Murid!A15 | B15: =IF(Murid!B15="","",Murid!B15) | C15: =IF(Murid!C15="","",Murid!C15) | D15: =IF(Murid!E15="","",Murid!E15) | G15: =IF(F15="","",IFERROR(VLOOKUP(F15,T_JUB,2,FALSE),0)) | I15: =IF(H15="","",IF(H15>=12,40,ROUND(H15*3.33,2))) | N15: =IF(COUNTA(J15:M15)=0,"",MIN(10,SUMPRODUCT((COUNTIF(J15:M15,L_KOM)>0)*S_KOM))) | P15: =IF(O15="","",IFERROR(VLOOKUP(O15,T_KHID,2,FALSE),0)) | S15: =IF(AND(Q15="",R15=""),"",IFERROR(INDEX(T_LIBAT,MATCH(Q15,L_PER,0),MATCH(R15,L_JENIS,0)),0)) | V15: =IF(AND(T15="",U15=""),"",IFERROR(INDEX(T_CAPAI,MATCH(T15,L_PER,0),MATCH(U15,L_KED,0)),0)) | W15: =IF(OR(B15="",E15="",COUNTA(F15,H15,J15:M15,O15,Q15:R15,T15:U15)=0),"",SUM(G15,I15,N15,P15,S15,V15)) | X15: =IF(W15="","",IF(Murid!F15="TL","TL",ROUND(W15/110*100,2)))
A16: =Murid!A16 | B16: =IF(Murid!B16="","",Murid!B16) | C16: =IF(Murid!C16="","",Murid!C16) | D16: =IF(Murid!E16="","",Murid!E16) | G16: =IF(F16="","",IFERROR(VLOOKUP(F16,T_JUB,2,FALSE),0)) | I16: =IF(H16="","",IF(H16>=12,40,ROUND(H16*3.33,2))) | N16: =IF(COUNTA(J16:M16)=0,"",MIN(10,SUMPRODUCT((COUNTIF(J16:M16,L_KOM)>0)*S_KOM))) | P16: =IF(O16="","",IFERROR(VLOOKUP(O16,T_KHID,2,FALSE),0)) | S16: =IF(AND(Q16="",R16=""),"",IFERROR(INDEX(T_LIBAT,MATCH(Q16,L_PER,0),MATCH(R16,L_JENIS,0)),0)) | V16: =IF(AND(T16="",U16=""),"",IFERROR(INDEX(T_CAPAI,MATCH(T16,L_PER,0),MATCH(U16,L_KED,0)),0)) | W16: =IF(OR(B16="",E16="",COUNTA(F16,H16,J16:M16,O16,Q16:R16,T16:U16)=0),"",SUM(G16,I16,N16,P16,S16,V16)) | X16: =IF(W16="","",IF(Murid!F16="TL","TL",ROUND(W16/110*100,2)))
... A1004: =Murid!A1004 | B1004: =IF(Murid!B1004="","",Murid!B1004) | C1004: =IF(Murid!C1004="","",Murid!C1004) | D1004: =IF(Murid!E1004="","",Murid!E1004) | G1004: =IF(F1004="","",IFERROR(VLOOKUP(F1004,T_JUB,2,FALSE),0)) | I1004: =IF(H1004="","",IF(H1004>=12,40,ROUND(H1004*3.33,2))) | N1004: =IF(COUNTA(J1004:M1004)=0,"",MIN(10,SUMPRODUCT((COUNTIF(J1004:M1004,L_KOM)>0)*S_KOM))) | P1004: =IF(O1004="","",IFERROR(VLOOKUP(O1004,T_KHID,2,FALSE),0)) | S1004: =IF(AND(Q1004="",R1004=""),"",IFERROR(INDEX(T_LIBAT,MATCH(Q1004,L_PER,0),MATCH(R1004,L_JENIS,0)),0)) | V1004: =IF(AND(T1004="",U1004=""),"",IFERROR(INDEX(T_CAPAI,MATCH(T1004,L_PER,0),MATCH(U1004,L_KED,0)),0)) | W1004: =IF(OR(B1004="",E1004="",COUNTA(F1004,H1004,J1004:M1004,O1004,Q1004:R1004,T1004:U1004)=0),"",SUM(G1004,I1004,N1004,P1004,S1004,V1004)) | X1004: =IF(W1004="","",IF(Murid!F1004="TL","TL",ROUND(W1004/110*100,2)))

Sheet SP
A1: SUKAN & PERMAINAN (SP)
A2: Isi petak kuning. Pelibatan & Pencapaian: ambil yang TERTINGGI (aktiviti utama atau tambahan). Jawatan, Komitmen & Khidmat: aktiviti utama sahaja.
F3: Jawatan | H3: Kehadiran | J3: Komitmen (maks. 4 pilihan) | O3: Khidmat Sumbangan | Q3: Pelibatan | T3: Pencapaian | W3: Markah
A4: Bil | B4: Nama Murid | C4: No. MyKad | D4: Kelas | E4: Unit / Aktiviti Utama | F4: Jawatan | G4: Skor Jawatan | H4: Bil. Hadir (0-12) | I4: Skor Hadir (40) | J4: Komitmen 1 | K4: Komitmen 2 | L4: Komitmen 3 | M4: Komitmen 4 | N4: Skor Komitmen (10) | O4: Khidmat Sumbangan | P4: Skor Khidmat (10) | Q4: Pelibatan: Peringkat | R4: Pelibatan: Jenis | S4: Skor Pelibatan (20) | T4: Pencapaian: Peringkat | U4: Pencapaian: Kedudukan | V4: Skor Pencapaian (20) | W4: Jumlah (110) | X4: Markah (100)
A5: =Murid!A5 | B5: =IF(Murid!B5="","",Murid!B5) | C5: =IF(Murid!C5="","",Murid!C5) | D5: =IF(Murid!E5="","",Murid!E5) | G5: =IF(F5="","",IFERROR(VLOOKUP(F5,T_JSP,2,FALSE),0)) | I5: =IF(H5="","",IF(H5>=12,40,ROUND(H5*3.33,2))) | N5: =IF(COUNTA(J5:M5)=0,"",MIN(10,SUMPRODUCT((COUNTIF(J5:M5,L_KOM)>0)*S_KOM))) | P5: =IF(O5="","",IFERROR(VLOOKUP(O5,T_KHID,2,FALSE),0)) | S5: =IF(AND(Q5="",R5=""),"",IFERROR(INDEX(T_LIBAT,MATCH(Q5,L_PER,0),MATCH(R5,L_JENIS,0)),0)) | V5: =IF(AND(T5="",U5=""),"",IFERROR(INDEX(T_CAPAI,MATCH(T5,L_PER,0),MATCH(U5,L_KED,0)),0)) | W5: =IF(OR(B5="",E5="",COUNTA(F5,H5,J5:M5,O5,Q5:R5,T5:U5)=0),"",SUM(G5,I5,N5,P5,S5,V5)) | X5: =IF(W5="","",IF(Murid!F5="TL","TL",ROUND(W5/110*100,2)))
A6: =Murid!A6 | B6: =IF(Murid!B6="","",Murid!B6) | C6: =IF(Murid!C6="","",Murid!C6) | D6: =IF(Murid!E6="","",Murid!E6) | G6: =IF(F6="","",IFERROR(VLOOKUP(F6,T_JSP,2,FALSE),0)) | I6: =IF(H6="","",IF(H6>=12,40,ROUND(H6*3.33,2))) | N6: =IF(COUNTA(J6:M6)=0,"",MIN(10,SUMPRODUCT((COUNTIF(J6:M6,L_KOM)>0)*S_KOM))) | P6: =IF(O6="","",IFERROR(VLOOKUP(O6,T_KHID,2,FALSE),0)) | S6: =IF(AND(Q6="",R6=""),"",IFERROR(INDEX(T_LIBAT,MATCH(Q6,L_PER,0),MATCH(R6,L_JENIS,0)),0)) | V6: =IF(AND(T6="",U6=""),"",IFERROR(INDEX(T_CAPAI,MATCH(T6,L_PER,0),MATCH(U6,L_KED,0)),0)) | W6: =IF(OR(B6="",E6="",COUNTA(F6,H6,J6:M6,O6,Q6:R6,T6:U6)=0),"",SUM(G6,I6,N6,P6,S6,V6)) | X6: =IF(W6="","",IF(Murid!F6="TL","TL",ROUND(W6/110*100,2)))
A7: =Murid!A7 | B7: =IF(Murid!B7="","",Murid!B7) | C7: =IF(Murid!C7="","",Murid!C7) | D7: =IF(Murid!E7="","",Murid!E7) | G7: =IF(F7="","",IFERROR(VLOOKUP(F7,T_JSP,2,FALSE),0)) | I7: =IF(H7="","",IF(H7>=12,40,ROUND(H7*3.33,2))) | N7: =IF(COUNTA(J7:M7)=0,"",MIN(10,SUMPRODUCT((COUNTIF(J7:M7,L_KOM)>0)*S_KOM))) | P7: =IF(O7="","",IFERROR(VLOOKUP(O7,T_KHID,2,FALSE),0)) | S7: =IF(AND(Q7="",R7=""),"",IFERROR(INDEX(T_LIBAT,MATCH(Q7,L_PER,0),MATCH(R7,L_JENIS,0)),0)) | V7: =IF(AND(T7="",U7=""),"",IFERROR(INDEX(T_CAPAI,MATCH(T7,L_PER,0),MATCH(U7,L_KED,0)),0)) | W7: =IF(OR(B7="",E7="",COUNTA(F7,H7,J7:M7,O7,Q7:R7,T7:U7)=0),"",SUM(G7,I7,N7,P7,S7,V7)) | X7: =IF(W7="","",IF(Murid!F7="TL","TL",ROUND(W7/110*100,2)))
A8: =Murid!A8 | B8: =IF(Murid!B8="","",Murid!B8) | C8: =IF(Murid!C8="","",Murid!C8) | D8: =IF(Murid!E8="","",Murid!E8) | G8: =IF(F8="","",IFERROR(VLOOKUP(F8,T_JSP,2,FALSE),0)) | I8: =IF(H8="","",IF(H8>=12,40,ROUND(H8*3.33,2))) | N8: =IF(COUNTA(J8:M8)=0,"",MIN(10,SUMPRODUCT((COUNTIF(J8:M8,L_KOM)>0)*S_KOM))) | P8: =IF(O8="","",IFERROR(VLOOKUP(O8,T_KHID,2,FALSE),0)) | S8: =IF(AND(Q8="",R8=""),"",IFERROR(INDEX(T_LIBAT,MATCH(Q8,L_PER,0),MATCH(R8,L_JENIS,0)),0)) | V8: =IF(AND(T8="",U8=""),"",IFERROR(INDEX(T_CAPAI,MATCH(T8,L_PER,0),MATCH(U8,L_KED,0)),0)) | W8: =IF(OR(B8="",E8="",COUNTA(F8,H8,J8:M8,O8,Q8:R8,T8:U8)=0),"",SUM(G8,I8,N8,P8,S8,V8)) | X8: =IF(W8="","",IF(Murid!F8="TL","TL",ROUND(W8/110*100,2)))
A9: =Murid!A9 | B9: =IF(Murid!B9="","",Murid!B9) | C9: =IF(Murid!C9="","",Murid!C9) | D9: =IF(Murid!E9="","",Murid!E9) | G9: =IF(F9="","",IFERROR(VLOOKUP(F9,T_JSP,2,FALSE),0)) | I9: =IF(H9="","",IF(H9>=12,40,ROUND(H9*3.33,2))) | N9: =IF(COUNTA(J9:M9)=0,"",MIN(10,SUMPRODUCT((COUNTIF(J9:M9,L_KOM)>0)*S_KOM))) | P9: =IF(O9="","",IFERROR(VLOOKUP(O9,T_KHID,2,FALSE),0)) | S9: =IF(AND(Q9="",R9=""),"",IFERROR(INDEX(T_LIBAT,MATCH(Q9,L_PER,0),MATCH(R9,L_JENIS,0)),0)) | V9: =IF(AND(T9="",U9=""),"",IFERROR(INDEX(T_CAPAI,MATCH(T9,L_PER,0),MATCH(U9,L_KED,0)),0)) | W9: =IF(OR(B9="",E9="",COUNTA(F9,H9,J9:M9,O9,Q9:R9,T9:U9)=0),"",SUM(G9,I9,N9,P9,S9,V9)) | X9: =IF(W9="","",IF(Murid!F9="TL","TL",ROUND(W9/110*100,2)))
A10: =Murid!A10 | B10: =IF(Murid!B10="","",Murid!B10) | C10: =IF(Murid!C10="","",Murid!C10) | D10: =IF(Murid!E10="","",Murid!E10) | G10: =IF(F10="","",IFERROR(VLOOKUP(F10,T_JSP,2,FALSE),0)) | I10: =IF(H10="","",IF(H10>=12,40,ROUND(H10*3.33,2))) | N10: =IF(COUNTA(J10:M10)=0,"",MIN(10,SUMPRODUCT((COUNTIF(J10:M10,L_KOM)>0)*S_KOM))) | P10: =IF(O10="","",IFERROR(VLOOKUP(O10,T_KHID,2,FALSE),0)) | S10: =IF(AND(Q10="",R10=""),"",IFERROR(INDEX(T_LIBAT,MATCH(Q10,L_PER,0),MATCH(R10,L_JENIS,0)),0)) | V10: =IF(AND(T10="",U10=""),"",IFERROR(INDEX(T_CAPAI,MATCH(T10,L_PER,0),MATCH(U10,L_KED,0)),0)) | W10: =IF(OR(B10="",E10="",COUNTA(F10,H10,J10:M10,O10,Q10:R10,T10:U10)=0),"",SUM(G10,I10,N10,P10,S10,V10)) | X10: =IF(W10="","",IF(Murid!F10="TL","TL",ROUND(W10/110*100,2)))
A11: =Murid!A11 | B11: =IF(Murid!B11="","",Murid!B11) | C11: =IF(Murid!C11="","",Murid!C11) | D11: =IF(Murid!E11="","",Murid!E11) | G11: =IF(F11="","",IFERROR(VLOOKUP(F11,T_JSP,2,FALSE),0)) | I11: =IF(H11="","",IF(H11>=12,40,ROUND(H11*3.33,2))) | N11: =IF(COUNTA(J11:M11)=0,"",MIN(10,SUMPRODUCT((COUNTIF(J11:M11,L_KOM)>0)*S_KOM))) | P11: =IF(O11="","",IFERROR(VLOOKUP(O11,T_KHID,2,FALSE),0)) | S11: =IF(AND(Q11="",R11=""),"",IFERROR(INDEX(T_LIBAT,MATCH(Q11,L_PER,0),MATCH(R11,L_JENIS,0)),0)) | V11: =IF(AND(T11="",U11=""),"",IFERROR(INDEX(T_CAPAI,MATCH(T11,L_PER,0),MATCH(U11,L_KED,0)),0)) | W11: =IF(OR(B11="",E11="",COUNTA(F11,H11,J11:M11,O11,Q11:R11,T11:U11)=0),"",SUM(G11,I11,N11,P11,S11,V11)) | X11: =IF(W11="","",IF(Murid!F11="TL","TL",ROUND(W11/110*100,2)))
A12: =Murid!A12 | B12: =IF(Murid!B12="","",Murid!B12) | C12: =IF(Murid!C12="","",Murid!C12) | D12: =IF(Murid!E12="","",Murid!E12) | G12: =IF(F12="","",IFERROR(VLOOKUP(F12,T_JSP,2,FALSE),0)) | I12: =IF(H12="","",IF(H12>=12,40,ROUND(H12*3.33,2))) | N12: =IF(COUNTA(J12:M12)=0,"",MIN(10,SUMPRODUCT((COUNTIF(J12:M12,L_KOM)>0)*S_KOM))) | P12: =IF(O12="","",IFERROR(VLOOKUP(O12,T_KHID,2,FALSE),0)) | S12: =IF(AND(Q12="",R12=""),"",IFERROR(INDEX(T_LIBAT,MATCH(Q12,L_PER,0),MATCH(R12,L_JENIS,0)),0)) | V12: =IF(AND(T12="",U12=""),"",IFERROR(INDEX(T_CAPAI,MATCH(T12,L_PER,0),MATCH(U12,L_KED,0)),0)) | W12: =IF(OR(B12="",E12="",COUNTA(F12,H12,J12:M12,O12,Q12:R12,T12:U12)=0),"",SUM(G12,I12,N12,P12,S12,V12)) | X12: =IF(W12="","",IF(Murid!F12="TL","TL",ROUND(W12/110*100,2)))
A13: =Murid!A13 | B13: =IF(Murid!B13="","",Murid!B13) | C13: =IF(Murid!C13="","",Murid!C13) | D13: =IF(Murid!E13="","",Murid!E13) | G13: =IF(F13="","",IFERROR(VLOOKUP(F13,T_JSP,2,FALSE),0)) | I13: =IF(H13="","",IF(H13>=12,40,ROUND(H13*3.33,2))) | N13: =IF(COUNTA(J13:M13)=0,"",MIN(10,SUMPRODUCT((COUNTIF(J13:M13,L_KOM)>0)*S_KOM))) | P13: =IF(O13="","",IFERROR(VLOOKUP(O13,T_KHID,2,FALSE),0)) | S13: =IF(AND(Q13="",R13=""),"",IFERROR(INDEX(T_LIBAT,MATCH(Q13,L_PER,0),MATCH(R13,L_JENIS,0)),0)) | V13: =IF(AND(T13="",U13=""),"",IFERROR(INDEX(T_CAPAI,MATCH(T13,L_PER,0),MATCH(U13,L_KED,0)),0)) | W13: =IF(OR(B13="",E13="",COUNTA(F13,H13,J13:M13,O13,Q13:R13,T13:U13)=0),"",SUM(G13,I13,N13,P13,S13,V13)) | X13: =IF(W13="","",IF(Murid!F13="TL","TL",ROUND(W13/110*100,2)))
A14: =Murid!A14 | B14: =IF(Murid!B14="","",Murid!B14) | C14: =IF(Murid!C14="","",Murid!C14) | D14: =IF(Murid!E14="","",Murid!E14) | G14: =IF(F14="","",IFERROR(VLOOKUP(F14,T_JSP,2,FALSE),0)) | I14: =IF(H14="","",IF(H14>=12,40,ROUND(H14*3.33,2))) | N14: =IF(COUNTA(J14:M14)=0,"",MIN(10,SUMPRODUCT((COUNTIF(J14:M14,L_KOM)>0)*S_KOM))) | P14: =IF(O14="","",IFERROR(VLOOKUP(O14,T_KHID,2,FALSE),0)) | S14: =IF(AND(Q14="",R14=""),"",IFERROR(INDEX(T_LIBAT,MATCH(Q14,L_PER,0),MATCH(R14,L_JENIS,0)),0)) | V14: =IF(AND(T14="",U14=""),"",IFERROR(INDEX(T_CAPAI,MATCH(T14,L_PER,0),MATCH(U14,L_KED,0)),0)) | W14: =IF(OR(B14="",E14="",COUNTA(F14,H14,J14:M14,O14,Q14:R14,T14:U14)=0),"",SUM(G14,I14,N14,P14,S14,V14)) | X14: =IF(W14="","",IF(Murid!F14="TL","TL",ROUND(W14/110*100,2)))
A15: =Murid!A15 | B15: =IF(Murid!B15="","",Murid!B15) | C15: =IF(Murid!C15="","",Murid!C15) | D15: =IF(Murid!E15="","",Murid!E15) | G15: =IF(F15="","",IFERROR(VLOOKUP(F15,T_JSP,2,FALSE),0)) | I15: =IF(H15="","",IF(H15>=12,40,ROUND(H15*3.33,2))) | N15: =IF(COUNTA(J15:M15)=0,"",MIN(10,SUMPRODUCT((COUNTIF(J15:M15,L_KOM)>0)*S_KOM))) | P15: =IF(O15="","",IFERROR(VLOOKUP(O15,T_KHID,2,FALSE),0)) | S15: =IF(AND(Q15="",R15=""),"",IFERROR(INDEX(T_LIBAT,MATCH(Q15,L_PER,0),MATCH(R15,L_JENIS,0)),0)) | V15: =IF(AND(T15="",U15=""),"",IFERROR(INDEX(T_CAPAI,MATCH(T15,L_PER,0),MATCH(U15,L_KED,0)),0)) | W15: =IF(OR(B15="",E15="",COUNTA(F15,H15,J15:M15,O15,Q15:R15,T15:U15)=0),"",SUM(G15,I15,N15,P15,S15,V15)) | X15: =IF(W15="","",IF(Murid!F15="TL","TL",ROUND(W15/110*100,2)))
A16: =Murid!A16 | B16: =IF(Murid!B16="","",Murid!B16) | C16: =IF(Murid!C16="","",Murid!C16) | D16: =IF(Murid!E16="","",Murid!E16) | G16: =IF(F16="","",IFERROR(VLOOKUP(F16,T_JSP,2,FALSE),0)) | I16: =IF(H16="","",IF(H16>=12,40,ROUND(H16*3.33,2))) | N16: =IF(COUNTA(J16:M16)=0,"",MIN(10,SUMPRODUCT((COUNTIF(J16:M16,L_KOM)>0)*S_KOM))) | P16: =IF(O16="","",IFERROR(VLOOKUP(O16,T_KHID,2,FALSE),0)) | S16: =IF(AND(Q16="",R16=""),"",IFERROR(INDEX(T_LIBAT,MATCH(Q16,L_PER,0),MATCH(R16,L_JENIS,0)),0)) | V16: =IF(AND(T16="",U16=""),"",IFERROR(INDEX(T_CAPAI,MATCH(T16,L_PER,0),MATCH(U16,L_KED,0)),0)) | W16: =IF(OR(B16="",E16="",COUNTA(F16,H16,J16:M16,O16,Q16:R16,T16:U16)=0),"",SUM(G16,I16,N16,P16,S16,V16)) | X16: =IF(W16="","",IF(Murid!F16="TL","TL",ROUND(W16/110*100,2)))
... A1004: =Murid!A1004 | B1004: =IF(Murid!B1004="","",Murid!B1004) | C1004: =IF(Murid!C1004="","",Murid!C1004) | D1004: =IF(Murid!E1004="","",Murid!E1004) | G1004: =IF(F1004="","",IFERROR(VLOOKUP(F1004,T_JSP,2,FALSE),0)) | I1004: =IF(H1004="","",IF(H1004>=12,40,ROUND(H1004*3.33,2))) | N1004: =IF(COUNTA(J1004:M1004)=0,"",MIN(10,SUMPRODUCT((COUNTIF(J1004:M1004,L_KOM)>0)*S_KOM))) | P1004: =IF(O1004="","",IFERROR(VLOOKUP(O1004,T_KHID,2,FALSE),0)) | S1004: =IF(AND(Q1004="",R1004=""),"",IFERROR(INDEX(T_LIBAT,MATCH(Q1004,L_PER,0),MATCH(R1004,L_JENIS,0)),0)) | V1004: =IF(AND(T1004="",U1004=""),"",IFERROR(INDEX(T_CAPAI,MATCH(T1004,L_PER,0),MATCH(U1004,L_KED,0)),0)) | W1004: =IF(OR(B1004="",E1004="",COUNTA(F1004,H1004,J1004:M1004,O1004,Q1004:R1004,T1004:U1004)=0),"",SUM(G1004,I1004,N1004,P1004,S1004,V1004)) | X1004: =IF(W1004="","",IF(Murid!F1004="TL","TL",ROUND(W1004/110*100,2)))

Sheet Ekstra
A1: EKSTRA KURIKULUM (maks. 10)
A2: Susunan sama seperti tab Ekstra Kurikulum dalam MOEIS. Khidmat Masyarakat: isi BILANGAN aktiviti (0-5) bagi setiap jenis. Skor Ekstra = skor tertinggi (anggaran).
E3: Perkhidmatan | G3: Anugerah Khas (maks. 1) | I3: Khidmat Masyarakat (bilangan aktiviti, maks. 5) | Q3: NILAM | S3: TIMSS dan PISA | U3: Ekstra
A4: Bil | B4: Nama Murid | C4: No. MyKad | D4: Kelas | E4: Perkhidmatan | F4: Skor | G4: Anugerah Khas | H4: Skor | I4: KM: KEJIRANAN/KOMUNITI | J4: KM: ALAM SEKITAR | K4: KM: BENCANA ALAM | L4: KM: KEROHANIAN | M4: KM: KHIDMAT JABATAN/AGENSI | N4: KM: KEBUDAYAAN/KESENIAN/INTEGRASI | O4: KM: INSANIAH | P4: Skor | Q4: NILAM | R4: Skor | S4: TIMSS / PISA | T4: Skor | U4: Skor Ekstra (10) | V4: Catatan
A5: =Murid!A5 | B5: =IF(Murid!B5="","",Murid!B5) | C5: =IF(Murid!C5="","",Murid!C5) | D5: =IF(Murid!E5="","",Murid!E5) | F5: =IF(E5="","",IFERROR(VLOOKUP(E5,T_PERK,2,FALSE),0)) | H5: =IF(G5="","",IFERROR(VLOOKUP(G5,T_ANUG,2,FALSE),0)) | P5: =IF(COUNTA(I5:O5)=0,"",MIN(10,SUM(I5:O5))) | R5: =IF(Q5="","",IFERROR(VLOOKUP(Q5,T_NILAM,2,FALSE),0)) | T5: =IF(S5="","",IFERROR(VLOOKUP(S5,T_TIMSS,2,FALSE),0)) | U5: =IF(COUNT(F5,H5,P5,R5,T5)=0,"",MIN(10,MAX(F5,H5,P5,R5,T5)))
A6: =Murid!A6 | B6: =IF(Murid!B6="","",Murid!B6) | C6: =IF(Murid!C6="","",Murid!C6) | D6: =IF(Murid!E6="","",Murid!E6) | F6: =IF(E6="","",IFERROR(VLOOKUP(E6,T_PERK,2,FALSE),0)) | H6: =IF(G6="","",IFERROR(VLOOKUP(G6,T_ANUG,2,FALSE),0)) | P6: =IF(COUNTA(I6:O6)=0,"",MIN(10,SUM(I6:O6))) | R6: =IF(Q6="","",IFERROR(VLOOKUP(Q6,T_NILAM,2,FALSE),0)) | T6: =IF(S6="","",IFERROR(VLOOKUP(S6,T_TIMSS,2,FALSE),0)) | U6: =IF(COUNT(F6,H6,P6,R6,T6)=0,"",MIN(10,MAX(F6,H6,P6,R6,T6)))
A7: =Murid!A7 | B7: =IF(Murid!B7="","",Murid!B7) | C7: =IF(Murid!C7="","",Murid!C7) | D7: =IF(Murid!E7="","",Murid!E7) | F7: =IF(E7="","",IFERROR(VLOOKUP(E7,T_PERK,2,FALSE),0)) | H7: =IF(G7="","",IFERROR(VLOOKUP(G7,T_ANUG,2,FALSE),0)) | P7: =IF(COUNTA(I7:O7)=0,"",MIN(10,SUM(I7:O7))) | R7: =IF(Q7="","",IFERROR(VLOOKUP(Q7,T_NILAM,2,FALSE),0)) | T7: =IF(S7="","",IFERROR(VLOOKUP(S7,T_TIMSS,2,FALSE),0)) | U7: =IF(COUNT(F7,H7,P7,R7,T7)=0,"",MIN(10,MAX(F7,H7,P7,R7,T7)))
A8: =Murid!A8 | B8: =IF(Murid!B8="","",Murid!B8) | C8: =IF(Murid!C8="","",Murid!C8) | D8: =IF(Murid!E8="","",Murid!E8) | F8: =IF(E8="","",IFERROR(VLOOKUP(E8,T_PERK,2,FALSE),0)) | H8: =IF(G8="","",IFERROR(VLOOKUP(G8,T_ANUG,2,FALSE),0)) | P8: =IF(COUNTA(I8:O8)=0,"",MIN(10,SUM(I8:O8))) | R8: =IF(Q8="","",IFERROR(VLOOKUP(Q8,T_NILAM,2,FALSE),0)) | T8: =IF(S8="","",IFERROR(VLOOKUP(S8,T_TIMSS,2,FALSE),0)) | U8: =IF(COUNT(F8,H8,P8,R8,T8)=0,"",MIN(10,MAX(F8,H8,P8,R8,T8)))
A9: =Murid!A9 | B9: =IF(Murid!B9="","",Murid!B9) | C9: =IF(Murid!C9="","",Murid!C9) | D9: =IF(Murid!E9="","",Murid!E9) | F9: =IF(E9="","",IFERROR(VLOOKUP(E9,T_PERK,2,FALSE),0)) | H9: =IF(G9="","",IFERROR(VLOOKUP(G9,T_ANUG,2,FALSE),0)) | P9: =IF(COUNTA(I9:O9)=0,"",MIN(10,SUM(I9:O9))) | R9: =IF(Q9="","",IFERROR(VLOOKUP(Q9,T_NILAM,2,FALSE),0)) | T9: =IF(S9="","",IFERROR(VLOOKUP(S9,T_TIMSS,2,FALSE),0)) | U9: =IF(COUNT(F9,H9,P9,R9,T9)=0,"",MIN(10,MAX(F9,H9,P9,R9,T9)))
A10: =Murid!A10 | B10: =IF(Murid!B10="","",Murid!B10) | C10: =IF(Murid!C10="","",Murid!C10) | D10: =IF(Murid!E10="","",Murid!E10) | F10: =IF(E10="","",IFERROR(VLOOKUP(E10,T_PERK,2,FALSE),0)) | H10: =IF(G10="","",IFERROR(VLOOKUP(G10,T_ANUG,2,FALSE),0)) | P10: =IF(COUNTA(I10:O10)=0,"",MIN(10,SUM(I10:O10))) | R10: =IF(Q10="","",IFERROR(VLOOKUP(Q10,T_NILAM,2,FALSE),0)) | T10: =IF(S10="","",IFERROR(VLOOKUP(S10,T_TIMSS,2,FALSE),0)) | U10: =IF(COUNT(F10,H10,P10,R10,T10)=0,"",MIN(10,MAX(F10,H10,P10,R10,T10)))
A11: =Murid!A11 | B11: =IF(Murid!B11="","",Murid!B11) | C11: =IF(Murid!C11="","",Murid!C11) | D11: =IF(Murid!E11="","",Murid!E11) | F11: =IF(E11="","",IFERROR(VLOOKUP(E11,T_PERK,2,FALSE),0)) | H11: =IF(G11="","",IFERROR(VLOOKUP(G11,T_ANUG,2,FALSE),0)) | P11: =IF(COUNTA(I11:O11)=0,"",MIN(10,SUM(I11:O11))) | R11: =IF(Q11="","",IFERROR(VLOOKUP(Q11,T_NILAM,2,FALSE),0)) | T11: =IF(S11="","",IFERROR(VLOOKUP(S11,T_TIMSS,2,FALSE),0)) | U11: =IF(COUNT(F11,H11,P11,R11,T11)=0,"",MIN(10,MAX(F11,H11,P11,R11,T11)))
A12: =Murid!A12 | B12: =IF(Murid!B12="","",Murid!B12) | C12: =IF(Murid!C12="","",Murid!C12) | D12: =IF(Murid!E12="","",Murid!E12) | F12: =IF(E12="","",IFERROR(VLOOKUP(E12,T_PERK,2,FALSE),0)) | H12: =IF(G12="","",IFERROR(VLOOKUP(G12,T_ANUG,2,FALSE),0)) | P12: =IF(COUNTA(I12:O12)=0,"",MIN(10,SUM(I12:O12))) | R12: =IF(Q12="","",IFERROR(VLOOKUP(Q12,T_NILAM,2,FALSE),0)) | T12: =IF(S12="","",IFERROR(VLOOKUP(S12,T_TIMSS,2,FALSE),0)) | U12: =IF(COUNT(F12,H12,P12,R12,T12)=0,"",MIN(10,MAX(F12,H12,P12,R12,T12)))
A13: =Murid!A13 | B13: =IF(Murid!B13="","",Murid!B13) | C13: =IF(Murid!C13="","",Murid!C13) | D13: =IF(Murid!E13="","",Murid!E13) | F13: =IF(E13="","",IFERROR(VLOOKUP(E13,T_PERK,2,FALSE),0)) | H13: =IF(G13="","",IFERROR(VLOOKUP(G13,T_ANUG,2,FALSE),0)) | P13: =IF(COUNTA(I13:O13)=0,"",MIN(10,SUM(I13:O13))) | R13: =IF(Q13="","",IFERROR(VLOOKUP(Q13,T_NILAM,2,FALSE),0)) | T13: =IF(S13="","",IFERROR(VLOOKUP(S13,T_TIMSS,2,FALSE),0)) | U13: =IF(COUNT(F13,H13,P13,R13,T13)=0,"",MIN(10,MAX(F13,H13,P13,R13,T13)))
A14: =Murid!A14 | B14: =IF(Murid!B14="","",Murid!B14) | C14: =IF(Murid!C14="","",Murid!C14) | D14: =IF(Murid!E14="","",Murid!E14) | F14: =IF(E14="","",IFERROR(VLOOKUP(E14,T_PERK,2,FALSE),0)) | H14: =IF(G14="","",IFERROR(VLOOKUP(G14,T_ANUG,2,FALSE),0)) | P14: =IF(COUNTA(I14:O14)=0,"",MIN(10,SUM(I14:O14))) | R14: =IF(Q14="","",IFERROR(VLOOKUP(Q14,T_NILAM,2,FALSE),0)) | T14: =IF(S14="","",IFERROR(VLOOKUP(S14,T_TIMSS,2,FALSE),0)) | U14: =IF(COUNT(F14,H14,P14,R14,T14)=0,"",MIN(10,MAX(F14,H14,P14,R14,T14)))
A15: =Murid!A15 | B15: =IF(Murid!B15="","",Murid!B15) | C15: =IF(Murid!C15="","",Murid!C15) | D15: =IF(Murid!E15="","",Murid!E15) | F15: =IF(E15="","",IFERROR(VLOOKUP(E15,T_PERK,2,FALSE),0)) | H15: =IF(G15="","",IFERROR(VLOOKUP(G15,T_ANUG,2,FALSE),0)) | P15: =IF(COUNTA(I15:O15)=0,"",MIN(10,SUM(I15:O15))) | R15: =IF(Q15="","",IFERROR(VLOOKUP(Q15,T_NILAM,2,FALSE),0)) | T15: =IF(S15="","",IFERROR(VLOOKUP(S15,T_TIMSS,2,FALSE),0)) | U15: =IF(COUNT(F15,H15,P15,R15,T15)=0,"",MIN(10,MAX(F15,H15,P15,R15,T15)))
A16: =Murid!A16 | B16: =IF(Murid!B16="","",Murid!B16) | C16: =IF(Murid!C16="","",Murid!C16) | D16: =IF(Murid!E16="","",Murid!E16) | F16: =IF(E16="","",IFERROR(VLOOKUP(E16,T_PERK,2,FALSE),0)) | H16: =IF(G16="","",IFERROR(VLOOKUP(G16,T_ANUG,2,FALSE),0)) | P16: =IF(COUNTA(I16:O16)=0,"",MIN(10,SUM(I16:O16))) | R16: =IF(Q16="","",IFERROR(VLOOKUP(Q16,T_NILAM,2,FALSE),0)) | T16: =IF(S16="","",IFERROR(VLOOKUP(S16,T_TIMSS,2,FALSE),0)) | U16: =IF(COUNT(F16,H16,P16,R16,T16)=0,"",MIN(10,MAX(F16,H16,P16,R16,T16)))
... A1004: =Murid!A1004 | B1004: =IF(Murid!B1004="","",Murid!B1004) | C1004: =IF(Murid!C1004="","",Murid!C1004) | D1004: =IF(Murid!E1004="","",Murid!E1004) | F1004: =IF(E1004="","",IFERROR(VLOOKUP(E1004,T_PERK,2,FALSE),0)) | H1004: =IF(G1004="","",IFERROR(VLOOKUP(G1004,T_ANUG,2,FALSE),0)) | P1004: =IF(COUNTA(I1004:O1004)=0,"",MIN(10,SUM(I1004:O1004))) | R1004: =IF(Q1004="","",IFERROR(VLOOKUP(Q1004,T_NILAM,2,FALSE),0)) | T1004: =IF(S1004="","",IFERROR(VLOOKUP(S1004,T_TIMSS,2,FALSE),0)) | U1004: =IF(COUNT(F1004,H1004,P1004,R1004,T1004)=0,"",MIN(10,MAX(F1004,H1004,P1004,R1004,T1004)))

Sheet Rumusan
A1: RUMUSAN MARKAH PAJSK (KOKURIKULUM)
A2: Semua dikira automatik. GPA = purata 2 markah terbaik (KP/UB/SP) + Ekstra, maksimum 100. Anggaran untuk semakan; markah MOEIS adalah muktamad.
A4: Bil | B4: Nama Murid | C4: No. MyKad | D4: Kelas | E4: KP (100) | F4: UB (100) | G4: SP (100) | H4: Purata 2 Terbaik | I4: Ekstra (10) | J4: GPA | K4: Gred | L4: Tahap
A5: =Murid!A5 | B5: =IF(Murid!B5="","",Murid!B5) | C5: =IF(Murid!C5="","",Murid!C5) | D5: =IF(Murid!E5="","",Murid!E5) | E5: =KP!X5 | F5: =UB!X5 | G5: =SP!X5 | H5: =IF(COUNT(E5:G5)=0,"",ROUND((LARGE(E5:G5,1)+IF(COUNT(E5:G5)>=2,LARGE(E5:G5,2),0))/2,2)) | I5: =Ekstra!U5 | J5: =IF(B5="","",IF(Murid!F5="TL","TL",IF(H5="","",MIN(100,ROUND(H5+N(I5),2))))) | K5: =IF(J5="","",IF(J5="TL","TL",IF(J5>=80,"A",IF(J5>=60,"B",IF(J5>=40,"C",IF(J5>=20,"D","E")))))) | L5: =IF(K5="","",IF(K5="A","Cemerlang",IF(K5="B","Kepujian",IF(K5="C","Baik",IF(K5="D","Kurang Memuaskan",IF(K5="E","Tidak Memuaskan","Tidak Laksana"))))))
A6: =Murid!A6 | B6: =IF(Murid!B6="","",Murid!B6) | C6: =IF(Murid!C6="","",Murid!C6) | D6: =IF(Murid!E6="","",Murid!E6) | E6: =KP!X6 | F6: =UB!X6 | G6: =SP!X6 | H6: =IF(COUNT(E6:G6)=0,"",ROUND((LARGE(E6:G6,1)+IF(COUNT(E6:G6)>=2,LARGE(E6:G6,2),0))/2,2)) | I6: =Ekstra!U6 | J6: =IF(B6="","",IF(Murid!F6="TL","TL",IF(H6="","",MIN(100,ROUND(H6+N(I6),2))))) | K6: =IF(J6="","",IF(J6="TL","TL",IF(J6>=80,"A",IF(J6>=60,"B",IF(J6>=40,"C",IF(J6>=20,"D","E")))))) | L6: =IF(K6="","",IF(K6="A","Cemerlang",IF(K6="B","Kepujian",IF(K6="C","Baik",IF(K6="D","Kurang Memuaskan",IF(K6="E","Tidak Memuaskan","Tidak Laksana"))))))
A7: =Murid!A7 | B7: =IF(Murid!B7="","",Murid!B7) | C7: =IF(Murid!C7="","",Murid!C7) | D7: =IF(Murid!E7="","",Murid!E7) | E7: =KP!X7 | F7: =UB!X7 | G7: =SP!X7 | H7: =IF(COUNT(E7:G7)=0,"",ROUND((LARGE(E7:G7,1)+IF(COUNT(E7:G7)>=2,LARGE(E7:G7,2),0))/2,2)) | I7: =Ekstra!U7 | J7: =IF(B7="","",IF(Murid!F7="TL","TL",IF(H7="","",MIN(100,ROUND(H7+N(I7),2))))) | K7: =IF(J7="","",IF(J7="TL","TL",IF(J7>=80,"A",IF(J7>=60,"B",IF(J7>=40,"C",IF(J7>=20,"D","E")))))) | L7: =IF(K7="","",IF(K7="A","Cemerlang",IF(K7="B","Kepujian",IF(K7="C","Baik",IF(K7="D","Kurang Memuaskan",IF(K7="E","Tidak Memuaskan","Tidak Laksana"))))))
A8: =Murid!A8 | B8: =IF(Murid!B8="","",Murid!B8) | C8: =IF(Murid!C8="","",Murid!C8) | D8: =IF(Murid!E8="","",Murid!E8) | E8: =KP!X8 | F8: =UB!X8 | G8: =SP!X8 | H8: =IF(COUNT(E8:G8)=0,"",ROUND((LARGE(E8:G8,1)+IF(COUNT(E8:G8)>=2,LARGE(E8:G8,2),0))/2,2)) | I8: =Ekstra!U8 | J8: =IF(B8="","",IF(Murid!F8="TL","TL",IF(H8="","",MIN(100,ROUND(H8+N(I8),2))))) | K8: =IF(J8="","",IF(J8="TL","TL",IF(J8>=80,"A",IF(J8>=60,"B",IF(J8>=40,"C",IF(J8>=20,"D","E")))))) | L8: =IF(K8="","",IF(K8="A","Cemerlang",IF(K8="B","Kepujian",IF(K8="C","Baik",IF(K8="D","Kurang Memuaskan",IF(K8="E","Tidak Memuaskan","Tidak Laksana"))))))
A9: =Murid!A9 | B9: =IF(Murid!B9="","",Murid!B9) | C9: =IF(Murid!C9="","",Murid!C9) | D9: =IF(Murid!E9="","",Murid!E9) | E9: =KP!X9 | F9: =UB!X9 | G9: =SP!X9 | H9: =IF(COUNT(E9:G9)=0,"",ROUND((LARGE(E9:G9,1)+IF(COUNT(E9:G9)>=2,LARGE(E9:G9,2),0))/2,2)) | I9: =Ekstra!U9 | J9: =IF(B9="","",IF(Murid!F9="TL","TL",IF(H9="","",MIN(100,ROUND(H9+N(I9),2))))) | K9: =IF(J9="","",IF(J9="TL","TL",IF(J9>=80,"A",IF(J9>=60,"B",IF(J9>=40,"C",IF(J9>=20,"D","E")))))) | L9: =IF(K9="","",IF(K9="A","Cemerlang",IF(K9="B","Kepujian",IF(K9="C","Baik",IF(K9="D","Kurang Memuaskan",IF(K9="E","Tidak Memuaskan","Tidak Laksana"))))))
A10: =Murid!A10 | B10: =IF(Murid!B10="","",Murid!B10) | C10: =IF(Murid!C10="","",Murid!C10) | D10: =IF(Murid!E10="","",Murid!E10) | E10: =KP!X10 | F10: =UB!X10 | G10: =SP!X10 | H10: =IF(COUNT(E10:G10)=0,"",ROUND((LARGE(E10:G10,1)+IF(COUNT(E10:G10)>=2,LARGE(E10:G10,2),0))/2,2)) | I10: =Ekstra!U10 | J10: =IF(B10="","",IF(Murid!F10="TL","TL",IF(H10="","",MIN(100,ROUND(H10+N(I10),2))))) | K10: =IF(J10="","",IF(J10="TL","TL",IF(J10>=80,"A",IF(J10>=60,"B",IF(J10>=40,"C",IF(J10>=20,"D","E")))))) | L10: =IF(K10="","",IF(K10="A","Cemerlang",IF(K10="B","Kepujian",IF(K10="C","Baik",IF(K10="D","Kurang Memuaskan",IF(K10="E","Tidak Memuaskan","Tidak Laksana"))))))
A11: =Murid!A11 | B11: =IF(Murid!B11="","",Murid!B11) | C11: =IF(Murid!C11="","",Murid!C11) | D11: =IF(Murid!E11="","",Murid!E11) | E11: =KP!X11 | F11: =UB!X11 | G11: =SP!X11 | H11: =IF(COUNT(E11:G11)=0,"",ROUND((LARGE(E11:G11,1)+IF(COUNT(E11:G11)>=2,LARGE(E11:G11,2),0))/2,2)) | I11: =Ekstra!U11 | J11: =IF(B11="","",IF(Murid!F11="TL","TL",IF(H11="","",MIN(100,ROUND(H11+N(I11),2))))) | K11: =IF(J11="","",IF(J11="TL","TL",IF(J11>=80,"A",IF(J11>=60,"B",IF(J11>=40,"C",IF(J11>=20,"D","E")))))) | L11: =IF(K11="","",IF(K11="A","Cemerlang",IF(K11="B","Kepujian",IF(K11="C","Baik",IF(K11="D","Kurang Memuaskan",IF(K11="E","Tidak Memuaskan","Tidak Laksana"))))))
A12: =Murid!A12 | B12: =IF(Murid!B12="","",Murid!B12) | C12: =IF(Murid!C12="","",Murid!C12) | D12: =IF(Murid!E12="","",Murid!E12) | E12: =KP!X12 | F12: =UB!X12 | G12: =SP!X12 | H12: =IF(COUNT(E12:G12)=0,"",ROUND((LARGE(E12:G12,1)+IF(COUNT(E12:G12)>=2,LARGE(E12:G12,2),0))/2,2)) | I12: =Ekstra!U12 | J12: =IF(B12="","",IF(Murid!F12="TL","TL",IF(H12="","",MIN(100,ROUND(H12+N(I12),2))))) | K12: =IF(J12="","",IF(J12="TL","TL",IF(J12>=80,"A",IF(J12>=60,"B",IF(J12>=40,"C",IF(J12>=20,"D","E")))))) | L12: =IF(K12="","",IF(K12="A","Cemerlang",IF(K12="B","Kepujian",IF(K12="C","Baik",IF(K12="D","Kurang Memuaskan",IF(K12="E","Tidak Memuaskan","Tidak Laksana"))))))
A13: =Murid!A13 | B13: =IF(Murid!B13="","",Murid!B13) | C13: =IF(Murid!C13="","",Murid!C13) | D13: =IF(Murid!E13="","",Murid!E13) | E13: =KP!X13 | F13: =UB!X13 | G13: =SP!X13 | H13: =IF(COUNT(E13:G13)=0,"",ROUND((LARGE(E13:G13,1)+IF(COUNT(E13:G13)>=2,LARGE(E13:G13,2),0))/2,2)) | I13: =Ekstra!U13 | J13: =IF(B13="","",IF(Murid!F13="TL","TL",IF(H13="","",MIN(100,ROUND(H13+N(I13),2))))) | K13: =IF(J13="","",IF(J13="TL","TL",IF(J13>=80,"A",IF(J13>=60,"B",IF(J13>=40,"C",IF(J13>=20,"D","E")))))) | L13: =IF(K13="","",IF(K13="A","Cemerlang",IF(K13="B","Kepujian",IF(K13="C","Baik",IF(K13="D","Kurang Memuaskan",IF(K13="E","Tidak Memuaskan","Tidak Laksana"))))))
A14: =Murid!A14 | B14: =IF(Murid!B14="","",Murid!B14) | C14: =IF(Murid!C14="","",Murid!C14) | D14: =IF(Murid!E14="","",Murid!E14) | E14: =KP!X14 | F14: =UB!X14 | G14: =SP!X14 | H14: =IF(COUNT(E14:G14)=0,"",ROUND((LARGE(E14:G14,1)+IF(COUNT(E14:G14)>=2,LARGE(E14:G14,2),0))/2,2)) | I14: =Ekstra!U14 | J14: =IF(B14="","",IF(Murid!F14="TL","TL",IF(H14="","",MIN(100,ROUND(H14+N(I14),2))))) | K14: =IF(J14="","",IF(J14="TL","TL",IF(J14>=80,"A",IF(J14>=60,"B",IF(J14>=40,"C",IF(J14>=20,"D","E")))))) | L14: =IF(K14="","",IF(K14="A","Cemerlang",IF(K14="B","Kepujian",IF(K14="C","Baik",IF(K14="D","Kurang Memuaskan",IF(K14="E","Tidak Memuaskan","Tidak Laksana"))))))
A15: =Murid!A15 | B15: =IF(Murid!B15="","",Murid!B15) | C15: =IF(Murid!C15="","",Murid!C15) | D15: =IF(Murid!E15="","",Murid!E15) | E15: =KP!X15 | F15: =UB!X15 | G15: =SP!X15 | H15: =IF(COUNT(E15:G15)=0,"",ROUND((LARGE(E15:G15,1)+IF(COUNT(E15:G15)>=2,LARGE(E15:G15,2),0))/2,2)) | I15: =Ekstra!U15 | J15: =IF(B15="","",IF(Murid!F15="TL","TL",IF(H15="","",MIN(100,ROUND(H15+N(I15),2))))) | K15: =IF(J15="","",IF(J15="TL","TL",IF(J15>=80,"A",IF(J15>=60,"B",IF(J15>=40,"C",IF(J15>=20,"D","E")))))) | L15: =IF(K15="","",IF(K15="A","Cemerlang",IF(K15="B","Kepujian",IF(K15="C","Baik",IF(K15="D","Kurang Memuaskan",IF(K15="E","Tidak Memuaskan","Tidak Laksana"))))))
A16: =Murid!A16 | B16: =IF(Murid!B16="","",Murid!B16) | C16: =IF(Murid!C16="","",Murid!C16) | D16: =IF(Murid!E16="","",Murid!E16) | E16: =KP!X16 | F16: =UB!X16 | G16: =SP!X16 | H16: =IF(COUNT(E16:G16)=0,"",ROUND((LARGE(E16:G16,1)+IF(COUNT(E16:G16)>=2,LARGE(E16:G16,2),0))/2,2)) | I16: =Ekstra!U16 | J16: =IF(B16="","",IF(Murid!F16="TL","TL",IF(H16="","",MIN(100,ROUND(H16+N(I16),2))))) | K16: =IF(J16="","",IF(J16="TL","TL",IF(J16>=80,"A",IF(J16>=60,"B",IF(J16>=40,"C",IF(J16>=20,"D","E")))))) | L16: =IF(K16="","",IF(K16="A","Cemerlang",IF(K16="B","Kepujian",IF(K16="C","Baik",IF(K16="D","Kurang Memuaskan",IF(K16="E","Tidak Memuaskan","Tidak Laksana"))))))
... A1004: =Murid!A1004 | B1004: =IF(Murid!B1004="","",Murid!B1004) | C1004: =IF(Murid!C1004="","",Murid!C1004) | D1004: =IF(Murid!E1004="","",Murid!E1004) | E1004: =KP!X1004 | F1004: =UB!X1004 | G1004: =SP!X1004 | H1004: =IF(COUNT(E1004:G1004)=0,"",ROUND((LARGE(E1004:G1004,1)+IF(COUNT(E1004:G1004)>=2,LARGE(E1004:G1004,2),0))/2,2)) | I1004: =Ekstra!U1004 | J1004: =IF(B1004="","",IF(Murid!F1004="TL","TL",IF(H1004="","",MIN(100,ROUND(H1004+N(I1004),2))))) | K1004: =IF(J1004="","",IF(J1004="TL","TL",IF(J1004>=80,"A",IF(J1004>=60,"B",IF(J1004>=40,"C",IF(J1004>=20,"D","E")))))) | L1004: =IF(K1004="","",IF(K1004="A","Cemerlang",IF(K1004="B","Kepujian",IF(K1004="C","Baik",IF(K1004="D","Kurang Memuaskan",IF(K1004="E","Tidak Memuaskan","Tidak Laksana"))))))

Sheet Rujukan
A1: JADUAL RUJUKAN SKOR
A2: Teks pilihan sama seperti MOEIS. Sumber skor: MOEIS = disahkan pada skrin MOEIS; Garis panduan = jadual PAJSK SM; Anggaran = belum disahkan. Jangan ubah sheet ini.
AG3: Skor Pelibatan | AL3: Skor Pencapaian
A4: Jawatan KP | B4: Skor | C4: Sumber | E4: Jawatan SP | F4: Skor | G4: Sumber | I4: Jawatan UB | J4: Skor | K4: Sumber | M4: Komitmen | N4: Skor | O4: Sumber | Q4: Khidmat Sumbangan | R4: Skor | S4: Sumber | U4: Peringkat | V4: Skor | W4: Sumber | Y4: Jenis Pelibatan | Z4: Skor | AA4: Sumber | AC4: Kedudukan | AD4: Skor | AE4: Sumber | AH4: PELIBATAN 1 | AI4: PELIBATAN 2 | AJ4: PELIBATAN 3 | AM4: JOHAN | AN4: NAIB JOHAN | AO4: KETIGA | AP4: KEEMPAT | AQ4: KELIMA | AS4: Perkhidmatan | AT4: Skor | AU4: Sumber | AW4: Anugerah Khas | AX4: Skor | AY4: Sumber | BA4: NILAM | BB4: Skor | BC4: Sumber | BE4: TIMSS dan PISA | BF4: Skor | BG4: Sumber | BI4: Status murid | BJ4: Skor | BK4: Sumber
A5: PENGERUSI | B5: 10 | C5: Anggaran | E5: PENGERUSI | F5: 10 | G5: Anggaran | I5: PENGERUSI | J5: 10 | K5: Anggaran | M5: MENUNJUKKAN KEPIMPINAN | N5: 3 | O5: Garis panduan | Q5: 1 - ATLET / PESERTA PROGRAM / PERTANDINGAN / KARNIVAL / KURSUS | R5: 10 | S5: Garis panduan | U5: ANTARABANGSA | Y5: PELIBATAN 1 - Atlet/Peserta | AC5: JOHAN | AG5: ANTARABANGSA | AH5: 20 | AI5: 15 | AJ5: 10 | AL5: ANTARABANGSA | AM5: 20 | AN5: 19 | AO5: 18 | AP5: 17 | AQ5: 16 | AS5: KETUA MURID/PENGERUSI | AT5: 10 | AU5: MOEIS | AW5: ANUGERAH REMAJA PERDANA - EMAS | AX5: 10 | AY5: Garis panduan | BA5: 5 BINTANG | BB5: 7 | BC5: Anggaran | BE5: ANTARABANGSA - TAHAP CEMERLANG | BF5: 10 | BG5: Garis panduan | BI5: TL | BK5: DITAKSIR = OFF
A6: NAIB PENGERUSI | B6: 8 | C6: Anggaran | E6: KAPTEN PASUKAN | F6: 10 | G6: Anggaran | I6: NAIB PENGERUSI | J6: 8 | K6: Anggaran | M6: MENGURUS AKTIVITI | N6: 3 | O6: Garis panduan | Q6: 2 - KEMAHIRAN KHUSUS (PENGADIL, JURULATIH, TEKNIKAL) | R6: 10 | S6: Garis panduan | U6: KEBANGSAAN | Y6: PELIBATAN 2 - AJK/Teknikal/Persembahan | AC6: NAIB JOHAN | AG6: KEBANGSAAN | AH6: 17 | AI6: 12 | AJ6: 8 | AL6: KEBANGSAAN | AM6: 17 | AN6: 16 | AO6: 15 | AP6: 14 | AQ6: 13 | AS6: TIMBALAN/PENOLONG KETUA MURID | AT6: 8 | AU6: MOEIS | AW6: ANUGERAH REMAJA PERDANA - PERAK | AX6: 7 | AY6: Garis panduan | BA6: 4 BINTANG | BB6: 6 | BC6: Anggaran | BE6: ANTARABANGSA | BF6: 8 | BG6: Garis panduan | BI6: KELUAR | BK6: Maklumat sahaja
A7: SETIAUSAHA | B7: 7 | C7: MOEIS | E7: KETUA RUMAH | F7: 10 | G7: Anggaran | I7: SETIAUSAHA | J7: 7 | K7: Anggaran | M7: MENYEDIA PERALATAN | N7: 2 | O7: Garis panduan | Q7: 3 - PERSEMBAHAN SELINGAN | R7: 8 | S7: Garis panduan | U7: NEGERI | Y7: PELIBATAN 3 - Penyokong/Sorak | AC7: KETIGA | AG7: NEGERI | AH7: 14 | AI7: 10 | AJ7: 6 | AL7: NEGERI | AM7: 14 | AN7: 13 | AO7: 12 | AP7: 11 | AQ7: 10 | AS7: PENGAWAS/PENGAWAS PUSAT SUMBER/KETUA ASRAMA/KETUA PRS/KETUA BADAR/KUARTERMASTER/PENGERUSI BADAN PERKHIDMATAN SEKOLAH | AT7: 7 | AU7: MOEIS | AW7: ANUGERAH REMAJA PERDANA - GANGSA | AX7: 5 | AY7: Garis panduan | BA7: 3 BINTANG | BB7: 5 | BC7: Anggaran | BE7: KEBANGSAAN | BF7: 6 | BG7: Garis panduan
A8: BENDAHARI | B8: 7 | C8: Anggaran | E8: NAIB PENGERUSI | F8: 8 | G8: Anggaran | I8: BENDAHARI | J8: 7 | K8: Anggaran | M8: MEMBANTU GURU ATAU RAKAN | N8: 2 | O8: Garis panduan | Q8: 4 - SOKONGAN (PERBARISAN, PERSEMBAHAN, SORAK / PENYOKONG) | R8: 5 | S8: Garis panduan | U8: BAHAGIAN (SABAH/SARAWAK) | AC8: KEEMPAT | AG8: BAHAGIAN (SABAH/SARAWAK) | AH8: 12 | AI8: 9 | AJ8: 5 | AL8: BAHAGIAN (SABAH/SARAWAK) | AM8: 12 | AN8: 11 | AO8: 10 | AP8: 9 | AQ8: 8 | AS8: PENOLONG KETUA ASRAMA/PENOLONG KETUA BADAR/AHLI LEMBAGA PENGARAH KOPERASI SEKOLAH | AT8: 6 | AU8: MOEIS | AW8: PROGRAM KEPIMPINAN GENERASI MADANI - TIER 3 | AX8: 7 | AY8: Garis panduan | BA8: 2 BINTANG | BB8: 4 | BC8: Anggaran
A9: NAIB SETIAUSAHA | B9: 6 | C9: Anggaran | E9: PENOLONG KETUA RUMAH | F9: 8 | G9: Anggaran | I9: NAIB SETIAUSAHA | J9: 6 | K9: Anggaran | M9: MENGEMAS PERALATAN | N9: 2 | O9: Garis panduan | U9: ZON/DAERAH | AC9: KELIMA | AG9: ZON/DAERAH | AH9: 11 | AI9: 8 | AJ9: 4 | AL9: ZON/DAERAH | AM9: 11 | AN9: 10 | AO9: 9 | AP9: 8 | AQ9: 7 | AS9: AJK UTAMA BADAN-BADAN PERKHIDMATAN ATAU PENGURUSAN/BENDAHARI/SETIAUSAHA/KETUA BIRO-ASRAMA/PRS/PENERIMA SIJIL DAN LENCANA SLAD/PROSTAR/PENGAWAS KOPERASI/KETUA KELAS/KETUA TINGKATAN | AT9: 5 | AU9: MOEIS | AW9: PROGRAM KEPIMPINAN GENERASI MADANI - TIER 2 | AX9: 4 | AY9: Garis panduan | BA9: 1 BINTANG | BB9: 3 | BC9: Anggaran
A10: NAIB BENDAHARI | B10: 6 | C10: Anggaran | E10: PENOLONG KAPTEN | F10: 8 | G10: Anggaran | I10: NAIB BENDAHARI | J10: 6 | K10: Anggaran | M10: MEMBERSIH KAWASAN | N10: 2 | O10: Garis panduan | U10: SEKOLAH | AG10: SEKOLAH | AH10: 0 | AI10: 0 | AJ10: 0 | AL10: SEKOLAH | AM10: 8 | AN10: 7 | AO10: 6 | AP10: 5 | AQ10: 4 | AS10: AJK KECIL BIRO/KETUA BILIK/KETUA DORM/AJK BADAR/PENERIMA SIJIL SLAD/PENOLONG KETUA KELAS/PENOLONG KETUA BILIK | AT10: 3 | AU10: MOEIS | AW10: ANUGERAH PENGAKAP RAJA / RAMBU PENGAKAP KANAK-KANAK | AX10: 10 | AY10: Garis panduan
A11: AHLI JAWATANKUASA | B11: 5 | C11: Anggaran | E11: SETIAUSAHA | F11: 7 | G11: Anggaran | I11: PEGAWAI WARAN KRS I & II | J11: 10 | K11: Garis panduan | M11: MENEPATI WAKTU | N11: 2 | O11: Garis panduan | AS11: PENGAWAS PUSAT SUMBER (TINGKATAN 6) | AT11: 6 | AU11: MOEIS | AW11: ANUGERAH PANDU PUTERI RAJA / PANDU PUTERI TUNAS KETUA PESURUHJAYA | AX11: 10 | AY11: Garis panduan
A12: AHLI AKTIF | B12: 4 | C12: MOEIS | E12: BENDAHARI | F12: 7 | G12: Anggaran | I12: STAF SARJAN KRS | J12: 8 | K12: Garis panduan | M12: MENUNJUKKAN MINAT | N12: 2 | O12: Garis panduan | AL12: Baris BAHAGIAN: anggaran (tiada dalam garis panduan) | AW12: ANUGERAH PUTERI AZ-ZAHRA / PUTERI BONGSU - PPIM | AX12: 10 | AY12: Garis panduan
A13: AHLI BIASA | B13: 2 | C13: MOEIS | E13: NAIB SETIAUSAHA | F13: 6 | G13: Anggaran | I13: SARJAN KRS | J13: 7 | K13: Garis panduan | M13: MENUNJUKKAN KESUNGGUHAN | N13: 2 | O13: Garis panduan | AW13: ANUGERAH GRAND PRIOR / PERISAI PERKHIDMATAN KHAS 1000 JAM EMAS - SJAM | AX13: 10 | AY13: Garis panduan
E14: NAIB BENDAHARI | F14: 6 | G14: Anggaran | I14: KOPERAL KRS | J14: 6 | K14: Garis panduan | M14: MENGIKUT ARAHAN | N14: 2 | O14: Garis panduan | AW14: ANUGERAH KHAS KOKURIKULUM DAN SUKAN - KEBANGSAAN | AX14: 10 | AY14: Garis panduan
